Workbook

Sheet INDEX
A1: LSD.RID.0.AR | B1: Arkansas Labor Statistics | C1: December 2025
A2: TID | B2: Title | C2: Month
A3: =#REF! -> #REF! | B3: =#REF! -> #REF! | C3: =#REF! -> #REF!
A4: =#REF! -> #REF! | B4: =#REF! -> #REF! | C4: =#REF! -> #REF!
A5: =CALC!A1 -> LSD.RID.0.AR.CALC | B5: =CALC!B1 -> Arkansas Labor Statistic Calculations | C5: =CALC!C1 -> December 2025
A6: =VALID!A1 -> LSD.RID.0.AR.VALID | B6: =VALID!B1 -> Arkansas Labor Statistic Calculation Validation | C6: =VALID!C1 -> December 2025
A7: =LFP!A1 -> LSD.RID.0.AR.LFP | B7: =LFP!B1 -> Arkansas Labor Force Population (LFP) | C7: =LFP!C1 -> December 2025
A8: =ETPR!A1 -> LSD.RID.0.AR.ETPR | B8: =ETPR!B1 -> Arkansas Employment-to-Population Ratio (ETPR) | C8: =ETPR!C1 -> December 2025
A9: =LFPR!A1 -> LSD.RID.0.AR.LFPR | B9: =LFPR!B1 -> Arkansas Labor Force Participation Rate (LFPR) | C9: =LFPR!C1 -> December 2025
A10: =U3R!A1 -> LSD.RID.0.AR.U3R | B10: =U3R!B1 -> Arkansas Unemployment Rate (U3R) | C10: =U3R!C1 -> December 2025
A11: =U6R!A1 -> LSD.RID.0.AR.U6R | B11: =U6R!B1 -> Arkansas Underemployment Rate (U6R) | C11: =U6R!C1 -> December 2025
A12: =WAVG!A1 -> LSD.RID.0.AR.WAVG | B12: =WAVG!B1 -> Arkansas Wage Average (WAVG) | C12: =WAVG!C1 -> December 2025
A13: =AIAVG!A1 -> LSD.RID.0.AR.AIAVG | B13: =AIAVG!B1 -> Arkansas Annual Income Average (AIAVG) | C13: =AIAVG!C1 -> December 2025
A14: =FPITREV!A1 -> LSD.RID.0.AR.FPITREV | B14: =FPITREV!B1 -> Arkansas Federal Personal Income Tax Revenue (FPITREV) | C14: =FPITREV!C1 -> December 2025
A15: =FPPTREV!A1 -> LSD.RID.0.AR.FPPTR | B15: =FPPTREV!B1 -> Arkansas Federal Personal Payrol Tax Revenue | C15: =FPPTREV!C1 -> December 2025
A16: =EITCREF!A1 -> LSD.RID.0.AR.EITCREF | B16: =EITCREF!B1 -> Arkansas Earned Income Tax Credit Refund | C16: =EITCREF!C1 -> December 2025
A17: =ACTCREF!A1 -> LSD.RID.0.AR.ACTCREF | B17: =ACTCREF!B1 -> Arkansas Additional Child Tax Credit Refund | C17: =ACTCREF!C1 -> December 2025
A18: =AOTCREF!A1 -> LSD.RID.0.AR.AOTCREF | B18: =AOTCREF!B1 -> Arkansas American Opportunity Tax Credit Refund | C18: =AOTCREF!C1 -> December 2025
A20: LSD.RID.0.AR.GLOSS | B20: Arkansas Labor Statistic Calculations | C20: Calculated formulae use parameters.
A21: GLOID | B21: Glossary Name | C21: Definition
A22: 0 | B22: RID | C22: Region ID
A23: 1 | B23: DES | C23: Department of Economic Security
A24: 2 | B24: LSD | C24: Labor Security Division
A25: 3 | B25: SLIID | C25: State Labor Industry ID
A26: 4 | B26: SLIVID | C26: State Labor Industry Visualization ID
A27: 5 | B27: INVID | C27: Invocation ID
A28: 6 | B28: RID | C28: Region ID
A29: 7 | B29: LFP | C29: Labor Force Population
A30: 8 | B30: ETPR | C30: Employment-to-Population Ratio
A31: 9 | B31: LFPR | C31: Labor Force Population Rate
... A44: 22 | B44: VALID | C44: Validations
A46: CALC.COL | B46: Calculation Table Columns (2-row header)
A47: Labor Industry Role (LIR) | D47: Labor Force Population (LFP) | H47: Employment-to-Population Ratio (ETPR) | L47: Labor Force Participation Rate (LFPR) | P47: Unemployment Rate (U3R) | T47: Underemployment Rate (U6R) | X47: Wage Average (WAVG) | AA47: Annual Income Average (AIAVG) | AD47: Authorized Immigrant Wage Average (AIWAVG) | AG47: Authorized Immigrant Annual Income Average (AIAIAVG) | AJ47: Unauthorized Immigrant Wage Average (UIWAVG) | AM47: Unauthorized Immigrant Annual Income Average (UIAIAVG) | AP47: American Wage Average (AWAVG) | AS47: American Annual Income Average (AAIAVG) | AV47: Federal Personal Income Tax Revenue (FPITREV) | AZ47: Federal Personal Payroll Tax Revenue (FPPTREV) | BD47: Earned Income Tax Credit Refund (EITCREF) | BH47: Additional Child Tax Credit Refund (ACTCREF) | BL47: AOTCREF | BP47: Employed Population (EP) | BT47: Average Weekly Hours Worked (AWHW) | BX47: Full-Time Employment Rate (FTER) | CB47: Part-Time Employment Rate (PTER) | CF47: Job Tenure Average (JTA) | CJ47: Turnover Rate (TR) | CN47: Labor Productivity (LP) | CR47: Education Level Required (ELR) | CV47: State/Local Tax Revenue (SLTR) | CZ47: Social Security/Medicare Contributions (SSMC) | DD47: Public Assistance Usage Rate (PAUR)
A48: LIRID | B48: Labor Industry Role (LIR) | C48: Labor Industry Role Level | D48: Labor Force Population | E48: Authorized Labor Force Population | F48: Unauthorized Labor Force Population | G48: American Labor Force Population | H48: Employment-to-Population Ratio | I48: Authorized Immigrant Employment-to-Population Ratio | J48: Unauthorized Immigrant Employment-to-Population Ratio | K48: American Employment-to-Population Ratio | L48: Labor Force Participation Rate (LFPR) | M48: Authorized Immigrant Labor Force Participation Rate (LFPR) | N48: Unauthorized Immigrant Labor Force Participation Rate (LFPR) | O48: American Labor Force Participation Rate (LFPR) | P48: Unemployment Rate | Q48: Authorized Immigrant Unemployment Rate | R48: Unauthorized Immigrant Unemployment Rate | S48: American Unemployment Rate | T48: Underemployment Rate | U48: Authorized Immigrant Underemployment Rate | V48: Unauthorized Immigrant Underemployment Rate | W48: American Underemployment Rate | X48: Wage Average ($ /hr) | Y48: Wage Min ($ /hr) | Z48: Wage Max ($ /hr) | AA48: Annual Income Average ($) | AB48: Annual Income Min ($) | AC48: Annual Income Max ($) | AD48: Authorized Immigrant Wage Average ($ /hr) | AE48: Authorized Immigrant Wage Min ($ /hr) | AF48: Authorized Immigrant Wage Max ($ /hr) | AG48: Authorized Immigrant Annual Income Average ($) | AH48: Authorized Immigrant Annual Income Min ($) | AI48: Authorized Immigrant Annual Income Max ($) | AJ48: Unauthorized Immigrant Wage Average ($ /hr) | AK48: Unauthorized Immigrant Wage Min ($ /hr) | AL48: Unauthorized Immigrant Wage Max ($ /hr) | AM48: Unauthorized Immigrant Annual Income Average ($) | AN48: Unauthorized Immigrant Annual Income Min ($) | AO48: Unauthorized Immigrant Annual Income Max ($) | AP48: American Wage Average ($ /hr) | AQ48: American Wage Min ($ /hr) | AR48: American Wage Max ($ /hr) | AS48: American Annual Income Average ($) | AT48: American Annual Income Min ($) | AU48: American Annual Income Max ($) | AV48: Federal Personal Income Tax Revenue ($) | AW48: Authorized Immigrant Federal Personal Income Tax Revenue ($) | AX48: Unauthorized Immigrant Federal Personal Income Tax Revenue ($) | AY48: American Federal Personal Income Tax Revenue ($) | AZ48: Payroll Tax Revenue ($) | BA48: Authorized Immigrant Payroll Tax Revenue ($) | BB48: Unauthorized Immigrant Payroll Tax Revenue ($) | BC48: American Payroll Tax Revenue ($) | BD48: EITC Credit Refund | BE48: Authorized Immigrant EITC Credit Refund | BF48: Unauthorized Immigrant EITC Credit Refund | BG48: American Effective Tax EITC Credit Refund | BH48: ACTC Credit Refund | BI48: Authorized Immigrant ACTC Credit Refund | BJ48: Unauthorized Immigrant ACTC Credit Refund | BK48: American Effective Tax ACTC Credit Refund | BL48: AOTC Credit Refund | BM48: Authorized Immigrant AOTC Credit Refund | BN48: Unauthorized Immigrant AOTC Credit Refund | BO48: American Effective Tax AOTC Credit Refund | BP48: Employed Population | BQ48: Authorized Immigrant Employed Population | BR48: Unauthorized Immigrant Employed Population | BS48: American Employed Population | BT48: Average Weekly Hours Worked | BU48: Authorized Immigrant Average Weekly Hours Worked | BV48: Unauthorized Immigrant Average Weekly Hours Worked | BW48: American Average Weekly Hours Worked | BX48: AWHW Min Hours | BY48: AWHW Max Hours | BZ48: Full-Time Employment Rate | CA48: Authorized Immigrant Full-Time Employment Rate | CB48: Unauthorized Immigrant Full-Time Employment Rate | CC48: American Full-Time Employment Rate | CD48: Part-Time Employment Rate | CE48: Authorized Immigrant Part-Time Employment Rate | CF48: Unauthorized Immigrant Part-Time Employment Rate | CG48: American Part-Time Employment Rate | CH48: Job Tenure Average (years) | CI48: Authorized Immigrant Job Tenure Average | CJ48: Unauthorized Immigrant Job Tenure Average | CK48: American Job Tenure Average | CL48: JTA Min Tenure | CM48: JTA Max Tenure | CN48: Turnover Rate | CO48: Authorized Immigrant Turnover Rate | CP48: Unauthorized Immigrant Turnover Rate | CQ48: American Turnover Rate | CR48: Labor Productivity ($/hr) | CS48: Authorized Immigrant Labor Productivity | CT48: Unauthorized Immigrant Labor Productivity | CU48: American Labor Productivity | CV48: Education Level Required Average | CW48: Authorized Immigrant Education Level Average | CX48: Unauthorized Immigrant Education Level Average | CY48: American Education Level Average | CZ48: State/Local Tax Revenue ($) | DA48: Authorized Immigrant State/Local Tax Revenue | DB48: Unauthorized Immigrant State/Local Tax Revenue | DC48: American State/Local Tax Revenue | DD48: Social Security/Medicare Contributions ($) | DE48: Authorized Immigrant Social Security/Medicare Contributions | DF48: Unauthorized Immigrant Social Security/Medicare Contributions | DG48: American Social Security/Medicare Contributions | DH48: Public Assistance Usage Rate | DI48: Authorized Immigrant Public Assistance Usage Rate | DJ48: Unauthorized Immigrant Public Assistance Usage Rate | DK48: American Public Assistance Usage Rate
A50: CALC.ROW | B50: Calculation Table Rows (3-column header)
A51: LIRID | B51: Labor Industry Role (LIR) | C51: All Roles
A52: 0 | B52: All Industries | C52: Worker
A53: 1 | B53: Agriculture | C53: Support
A54: 2 | B54: Agriculture | C54: Worker
A55: 3 | B55: Construction | C55: Support
...

Sheet FORM
A1: LSD.REF.AR.FORM | B1: Arkansas Labor Statistic Logic Formulae | C1: NaN | D1: NaN | E1: December 2025
A2: FID Group | B2: FID | C2: Formula Name | D2: Formula (using PARAMETERS) | E2: Logic / Key Inputs | F2: Notes / Machine Instruction
A3: S0 - Shared/Base | B3: S0.0 | C3: Industry Employment Total | D3: T_i = PARAMETERS!TOTAL_NONFARM_AR * PARAMETERS!INDUSTRY_SHARE[i] | E3: BLS CES prorated | F3: Sum to BLS_EP_TOTAL_TARGET
A4: S0 - Shared/Base | B4: S0.1 | C4: Role Proration | D4: ROLE_WORKER_i = T_i * PARAMETERS!ROLE_PRORATE_WORKER_IND[i] | E4: Worker/Support split | F4: AR ACS-derived
A5: S0 - Shared/Base | B5: S0.2 | C5: Group Share Proration | D5: AUTH_SHARE_i = PARAMETERS!AUTH_SHARE_IND[i] | E5: Auth/Unauth/American split | F5: Cap UNAUTH_LF_CAP
A6: S0 - Shared/Base | B6: S0.3 | C6: Data Fusion Weighted Average | D6: value_i = (BLS_i * W_BLS + ACS_i * W_ACS + MPI_i * W_MPI) / sum weights | E6: Combine sources | F6: Weights: BLS 0.97, ACS 0.65, MPI 0.55
A7: S0 - Shared/Base | B7: S0.4 | C7: Labor Force Population Back-Calc | D7: LFP_total_i = EP_total_i / ETPR_total_i | E7: Derive LFP | F7: Apply scale
A8: S0 - Shared/Base | B8: S0.5 | C8: Employed Population by Group | D8: EP_total_i = T_i | E8: Direct proration | F8: Apply calibration
A9: S0 - Shared/Base | B9: S0.6 | C9: ETPR Hard Capped | D9: ETPR_total_i = MIN(1, EP_total_i / LFP_total_i) | E9: Ratio capped ≤1 | F9: Match state ETPR
A10: LFP Group | B10: S1.0 | C10: Labor Force Population by Group | D10: LFP_amer_i = PARAMETERS!LFPR_AMER_BASE[i] * pop | E10: Baseline + factors | F10: Blend S0.3; match total
A11: LFP Group | B11: 700.1 | C11: Global LF Calibration | D11: LFP_total_state = PARAMETERS!BLS_LF_TOTAL_TARGET | E11: Force match | F11: Apply last
A12: ETPR Group | B12: S1.1 | C12: ETPR by Group | D12: ETPR_amer_i = PARAMETERS!ETPR_AMER_BASE[i] | E12: Baseline + factors | F12: Cap ≤1; match 0.958
A13: ETPR Group | B13: 700.6 | C13: Global ETPR Calibration | D13: Adjust proportionally to match BLS | E13: Redistribute | F13: Post-sum
A14: LFPR Group | B14: S1.2 | C14: LFPR by Group | D14: LFPR_amer_i = PARAMETERS!LFPR_AMER_BASE[i] | E14: Baseline + factors | F14: Match 0.59
A15: LFPR Group | B15: 700.1 | C15: Global LFPR Calibration | D15: LFPR_total_state = PARAMETERS!BLS_LFPR_TARGET | E15: Force match | F15: Consistent with LFP
A16: U3R Group | B16: S1.3 | C16: U3R by Group | D16: U3R_amer_i = PARAMETERS!U3R_AMER_BASE[i] | E16: Baseline + factors | F16: Match 0.042
A17: U3R Group | B17: 700.2 | C17: Global U3R Calibration | D17: U3R_total_state = PARAMETERS!BLS_U3R_TARGET | E17: Redistribute residuals | F17: Exact
A18: U6R Group | B18: S1.4 | C18: U6R by Group | D18: U6R_amer_i = U3R_amer_i * PARAMETERS!U6_U3_RATIO_IND[i] | E18: Scale from U3R | F18: Blend BLS alt; ±18% uncertainty
A19: WAVG Group | B19: S2.0 | C19: Wage Average by Group | D19: WAVG_amer_i = PARAMETERS!WAVG_AMER_IND[i] | E19: Baseline + gaps | F19: Blend; floor at min wage
A20: WAVG Group | B20: 700.3 | C20: Global Wage Calibration | D20: WAVG_total_state = PARAMETERS!BLS_WAVG_TARGET | E20: Scale proportionally | F20: Align to $29.76
A21: AIAVG Group | B21: S2.1 | C21: Annual Income Average by Group | D21: AIAVG_amer_i = WAVG_amer_i * PARAMETERS!AWHW_IND[i] * 52 * PARAMETERS!OVERTIME_ADJ_IND[i] | E21: Annualize wages | F21: Apply gaps; 90% accuracy
A22: FPITREV Group | B22: S3.0 | C22: Federal PIT Revenue by Group | D22: FPITREV_amer_i = AIAVG_amer_i * EP_amer_i * PARAMETERS!FED_PIT_RATE_AMER | E22: Effective rates | F22: Blend IRS/CBO; unauth filing 60%
A23: FPPTREV Group | B23: S3.1 | C23: Federal Payroll Tax Revenue by Group | D23: FPPTREV_amer_i = AIAVG_amer_i * EP_amer_i * PARAMETERS!FED_PAYROLL_RATE | E23: 7.65%; unauth partial | F23: 90% accuracy
A24: EITCREF Group | B24: S3.2 | C24: EITC Credit Refund by Group | D24: EITCREF_total_i = PARAMETERS!EITC_TOTAL_AR * (EP_total_i / PARAMETERS!TOTAL_NONFARM_AR) | E24: Prorate IRS; unauth 0 | F24: Industry eligibility
A25: ACTCREF Group | B25: S3.3 | C25: ACTC Refund by Group | D25: ACTCREF_total_i = PARAMETERS!ACTC_TOTAL_AR * (EP_total_i / PARAMETERS!TOTAL_NONFARM_AR) | E25: Prorate; unauth partial | F25: Family-based
A26: AOTCREF Group | B26: S3.4 | C26: AOTC Refund by Group | D26: AOTCREF_total_i = PARAMETERS!AOTC_TOTAL_AR * (EP_total_i / PARAMETERS!TOTAL_NONFARM_AR) | E26: Prorate; unauth low | F26: Education barriers
A27: S4 - Derived | B27: S4.0 | C27: Full-Time Employment Rate | D27: FTER_total_i = weighted sum | E27: >35 hours; unauth higher | F27: AR CPS adj.
A28: S4 - Derived | B28: S4.1 | C28: Part-Time Employment Rate | D28: PTER_total_i = 1 - FTER_total_i | E28: Complement | F28: Derived
A29: S4 - Derived | B29: S4.2 | C29: Job Tenure Average | D29: JTA_total_i = weighted sum | E29: BLS/CPS; immigrants lower | F29: AR adj.
A30: S4 - Derived | B30: S4.3 | C30: Turnover Rate | D30: TR_total_i = weighted sum | E30: JOLTS; unauth higher | F30: AR reference
A31: S4 - Derived | B31: S4.4 | C31: Labor Productivity | D31: LP_total_i = weighted sum | E31: BEA/BLS per hour | F31: AR GDP adj.
A32: S4 - Derived | B32: S4.5 | C32: Public Assistance Usage Rate | D32: PAUR_total_i = weighted sum | E32: Census/CMS; unauth lower | F32: AR SNAP/Medicaid
A33: 700 - Calibration | B33: 700 | C33: Global Employment Calibration | D33: EP_total_state = PARAMETERS!BLS_EP_TOTAL_TARGET | E33: Force match CES | F33: Highest priority
A34: 700 - Calibration | B34: 700.1 | C34: Global LF & LFPR Calibration | D34: LFP_total_state = PARAMETERS!BLS_LF_TOTAL_TARGET | E34: Match LAUS | F34: Consistency with EP
A35: 700 - Calibration | B35: 700.2 | C35: U3R Global Calibration | D35: U3R_total_state = PARAMETERS!BLS_U3R_TARGET | E35: Exact 4.2% | F35: Redistribute
A36: 700 - Calibration | B36: 700.3 | C36: Wage & Income Global Calibration | D36: WAVG_total_state = PARAMETERS!BLS_WAVG_TARGET | E36: Align $29.76 | F36: Post-group
A37: 700 - Calibration | B37: 700.4 | C37: Unauthorized LF Cap Enforcement | D37: Scale UNAUTH_SHARE_i if sum > UNAUTH_LF_CAP | E37: Cap ~50k | F37: Prevents over-allocation
A38: 700 - Calibration | B38: 700.5 | C38: Seasonal & Regional Adjustment | D38: Apply AR-specific seasonal/regional factors | E38: BLS indices & county | F38: Before final
A39: 800 - AR-Specific | B39: 800 | C39: Poultry Sector Override | D39: T_poultry_i = T_ag_i * PARAMETERS!POULTRY_SHARE_AR + PARAMETERS!POULTRY_ADJUST | E39: Separate poultry | F39: Tyson-heavy
A40: 800 - AR-Specific | B40: 800.1 | C40: County/Regional Differential | D40: U3R_nw_ar = U3R_total * PARAMETERS!NW_AR_U3R_FACTOR | E40: Regional adj. | F40: NW AR lower U3R
...

Sheet PARAM
A1: LSD.REF.AR.PARAM | B1: Arkansas Labor Statistic Logic Parameters | C1: NaN | D1: NaN | E1: December 2025 | F1: NaN | G1: NaN | H1: NaN
A2: PID | B2: Parameter Name | C2: Value | D2: State / Description | E2: Notes / Sources | F2: Confidence Rating | G2: Confidence Source Note | H2: Last Updated / Source Note
A3: P001 | B3: TOTAL_NONFARM_AR | C3: 1399.4 | D3: AR / Total nonfarm payroll employment (thousands) | E3: BLS CES Dec 2025 | F3: High | G3: BLS CES Jan 2026 release | H3: February 13, 2026
A4: P002 | B4: AG_EMPLOYMENT_AR | C4: 35 | D4: AR / Agriculture (thousands, incl. self-employed/poultry) | E4: BLS CES + ACS + poultry adj. | F4: Medium-High | G4: BLS + AR ag data; Tyson emphasis | H4: February 13, 2026
A5: P003 | B5: CONSTR_EMPLOYMENT_AR | C5: 65 | D5: AR / Construction (thousands) | E5: BLS CES Dec 2025 | F5: High | G5: BLS CES Jan 2026 release | H5: February 13, 2026
A6: P004 | B6: MANU_EMPLOYMENT_AR | C6: 165.6 | D6: AR / Manufacturing (thousands) | E6: BLS CES Dec 2025 | F6: High | G6: BLS CES Jan 2026 release | H6: February 13, 2026
A7: P005 | B7: TRADE_TRANS_UTIL_EMPLOYMENT_AR | C7: 279.2 | D7: AR / Trade, Transportation, Utilities (thousands) | E7: BLS CES Dec 2025 | F7: High | G7: BLS CES Jan 2026 release | H7: February 13, 2026
A8: P006 | B8: INFO_EMPLOYMENT_AR | C8: 11.7 | D8: AR / Information (thousands) | E8: BLS CES Dec 2025 | F8: High | G8: BLS CES Jan 2026 release | H8: February 13, 2026
A9: P007 | B9: FIN_ACT_EMPLOYMENT_AR | C9: 70 | D9: AR / Financial Activities (thousands) | E9: BLS CES Dec 2025 | F9: High | G9: BLS CES Jan 2026 release | H9: February 13, 2026
A10: P008 | B10: PROF_BUS_SERV_EMPLOYMENT_AR | C10: 164.5 | D10: AR / Professional & Business Services (thousands) | E10: BLS CES Dec 2025 | F10: High | G10: BLS CES Jan 2026 release | H10: February 13, 2026
A11: P009 | B11: EDUC_HEALTH_EMPLOYMENT_AR | C11: 224.5 | D11: AR / Private Education & Health Services (thousands) | E11: BLS CES Dec 2025 | F11: High | G11: BLS CES Jan 2026 release | H11: February 13, 2026
A12: P010 | B12: LEIS_HOSP_EMPLOYMENT_AR | C12: 133 | D12: AR / Leisure & Hospitality (thousands) | E12: BLS CES Dec 2025 | F12: High | G12: BLS CES Jan 2026 release | H12: February 13, 2026
A13: P011 | B13: OTHER_SERV_EMPLOYMENT_AR | C13: 65.2 | D13: AR / Other Services (thousands) | E13: BLS CES Dec 2025 | F13: High | G13: BLS CES Jan 2026 release | H13: February 13, 2026
A14: P012 | B14: BLS_EP_TOTAL_TARGET | C14: 1399400 | D14: Target employed population (nonfarm payroll match) | E14: Derived from TOTAL_NONFARM_AR * 1000 | F14: High | G14: BLS alignment | H14: February 13, 2026
... A42: P040 | B42: FISCAL_MULT | C42: 0.12 | D42: Fiscal multiplier for labor impact | E42: ITEP estimate | F42: Medium | G42: AR-specific adj. | H42: February 13, 2026
A43: P041 | B43: INDUSTRY_SHARE[i] | C43: Varies | D43: Industry share of nonfarm (e.g., manu = 0.118, trade = 0.2) | E43: BLS CES prorated | F43: High | G43: Sum to 1 | H43: February 13, 2026
A44: P042 | B44: SEASONAL_ADJ_DEC | C44: 1.02 | D44: December seasonal adjustment (hospitality/ag boost) | E44: BLS indices | F44: Medium | G44: AR-specific | H44: February 13, 2026
A45: P043 | B45: WAGE_GAP_AUTH | C45: 0.08 | D45: Wage gap factor for authorized immigrants | E45: ACS | F45: Medium | G45: Relative to American | H45: February 13, 2026
A46: P044 | B46: WAGE_GAP_UNAUTH | C46: 0.22 | D46: Wage gap factor for unauthorized immigrants | E46: MPI | F46: Medium | G46: Relative to American | H46: February 13, 2026
A47: P045 | B47: STATE_LOCAL_TAX_RATE | C47: 0.1 | D47: Effective state/local tax rate | E47: ITEP AR | F47: Medium | G47: Applied to income | H47: February 13, 2026
A48: P046 | B48: SS_MEDICARE_RATE | C48: 0.0765 | D48: SS/Medicare contribution rate | E48: IRS | F48: High | G48: Matches payroll | H48: February 13, 2026
A49: P047 | B49: PAUR_AMER_BASE[i] | C49: 0.13 | D49: Base public assistance usage rate for American workers per industry | E49: Census/CMS | F49: Medium | G49: Industry-specific | H49: February 13, 2026
A50: P048 | B50: PAUR_AUTH_BASE[i] | C50: 0.08 | D50: Base for authorized immigrants | E50: Census/CMS | F50: Medium | G50: Lower due to eligibility | H50: February 13, 2026
A51: P049 | B51: PAUR_UNAUTH_BASE[i] | C51: 0.06 | D51: Base for unauthorized immigrants | E51: Census/CMS | F51: Medium | G51: Very low eligibility | H51: February 13, 2026
A52: P050 | B52: FTER_BASE_IND[i] | C52: 0.68 | D52: Base full-time employment rate per industry | E52: BLS CPS | F52: High | G52: AR adj. | H52: February 13, 2026
A53: P051 | B53: JTA_BASE_IND[i] | C53: 4.5 | D53: Base job tenure average per industry (years) | E53: BLS JOLTS | F53: Medium | G53: Immigrants lower | H53: February 13, 2026
A54: P052 | B54: TR_BASE_IND[i] | C54: 0.45 | D54: Base turnover rate per industry | E54: BLS JOLTS | F54: Medium | G54: Unauthorized higher | H54: February 13, 2026
A55: P053 | B55: LP_BASE_IND[i] | C55: 65 | D55: Base labor productivity per industry ($/hr) | E55: BEA/BLS | F55: Medium | G55: Industry-specific | H55: February 13, 2026
A56: P054 | B56: ELR_BASE_IND[i] | C56: 3 | D56: Base education level required per industry (1=HS, 2=Some College, 3=Bachelors, etc.) | E56: BLS OOH | F56: Medium | G56: Immigrants lower | H56: February 13, 2026

Sheet CALC
A1: LSD.RID.0.AR.CALC | B1: Arkansas Labor Statistic Calculations | C1: December 2025
A2: Labor Industry Role (LIR) | D2: Labor Force Population (LFP) | H2: Employment-to-Population Ratio (ETPR) | L2: Labor Force Participation Rate (LFPR) | P2: Unemployment Rate (U3R) | T2: Underemployment Rate (U6R) | X2: Wage Average (WAVG) | AA2: Annual Income Average (AIAVG) | AD2: Authorized Immigrant Wage Average (AIWAVG) | AG2: Authorized Immigrant Annual Income Average (AIAIAVG) | AJ2: Unauthorized Immigrant Wage Average (UIWAVG) | AM2: Unauthorized Immigrant Annual Income Average (UIAIAVG) | AP2: American Wage Average (AWAVG) | AS2: American Annual Income Average (AAIAVG) | AV2: Federal Personal Income Tax Revenue (FPITREV) | AZ2: Federal Personal Payroll Tax Revenue (FPPTREV) | BD2: Earned Income Tax Credit Refund (EITCREF) | BH2: Additional Child Tax Credit Refund (ACTCREF) | BL2: AOTCREF | BP2: Employed Population (EP) | BT2: Average Weekly Hours Worked (AWHW) | BX2: Full-Time Employment Rate (FTER) | CB2: Part-Time Employment Rate (PTER) | CF2: Job Tenure Average (JTA) | CJ2: Turnover Rate (TR) | CN2: Labor Productivity (LP) | CR2: Education Level Required (ELR) | CV2: State/Local Tax Revenue (SLTR) | CZ2: Social Security/Medicare Contributions (SSMC) | DD2: Public Assistance Usage Rate (PAUR)
A3: LIRID | B3: Labor Industry Role (LIR) | C3: Labor Industry Role Level | D3: Labor Force Population | E3: Authorized Labor Force Population | F3: Unauthorized Labor Force Population | G3: American Labor Force Population | H3: Employment-to-Population Ratio | I3: Authorized Immigrant Employment-to-Population Ratio | J3: Unauthorized Immigrant Employment-to-Population Ratio | K3: American Employment-to-Population Ratio | L3: Labor Force Participation Rate (LFPR) | M3: Authorized Immigrant Labor Force Participation Rate (LFPR) | N3: Unauthorized Immigrant Labor Force Participation Rate (LFPR) | O3: American Labor Force Participation Rate (LFPR) | P3: Unemployment Rate | Q3: Authorized Immigrant Unemployment Rate | R3: Unauthorized Immigrant Unemployment Rate | S3: American Unemployment Rate | T3: Underemployment Rate | U3: Authorized Immigrant Underemployment Rate | V3: Unauthorized Immigrant Underemployment Rate | W3: American Underemployment Rate | X3: Wage Average ($ /hr) | Y3: Wage Min ($ /hr) | Z3: Wage Max ($ /hr) | AA3: Annual Income Average ($) | AB3: Annual Income Min ($) | AC3: Annual Income Max ($) | AD3: Authorized Immigrant Wage Average ($ /hr) | AE3: Authorized Immigrant Wage Min ($ /hr) | AF3: Authorized Immigrant Wage Max ($ /hr) | AG3: Authorized Immigrant Annual Income Average ($) | AH3: Authorized Immigrant Annual Income Min ($) | AI3: Authorized Immigrant Annual Income Max ($) | AJ3: Unauthorized Immigrant Wage Average ($ /hr) | AK3: Unauthorized Immigrant Wage Min ($ /hr) | AL3: Unauthorized Immigrant Wage Max ($ /hr) | AM3: Unauthorized Immigrant Annual Income Average ($) | AN3: Unauthorized Immigrant Annual Income Min ($) | AO3: Unauthorized Immigrant Annual Income Max ($) | AP3: American Wage Average ($ /hr) | AQ3: American Wage Min ($ /hr) | AR3: American Wage Max ($ /hr) | AS3: American Annual Income Average ($) | AT3: American Annual Income Min ($) | AU3: American Annual Income Max ($) | AV3: Federal Personal Income Tax Revenue ($) | AW3: Authorized Immigrant Federal Personal Income Tax Revenue ($) | AX3: Unauthorized Immigrant Federal Personal Income Tax Revenue ($) | AY3: American Federal Personal Income Tax Revenue ($) | AZ3: Payroll Tax Revenue ($) | BA3: Authorized Immigrant Payroll Tax Revenue ($) | BB3: Unauthorized Immigrant Payroll Tax Revenue ($) | BC3: American Payroll Tax Revenue ($) | BD3: EITC Credit Refund | BE3: Authorized Immigrant EITC Credit Refund | BF3: Unauthorized Immigrant EITC Credit Refund | BG3: American Effective Tax EITC Credit Refund | BH3: ACTC Credit Refund | BI3: Authorized Immigrant ACTC Credit Refund | BJ3: Unauthorized Immigrant ACTC Credit Refund | BK3: American Effective Tax ACTC Credit Refund | BL3: AOTC Credit Refund | BM3: Authorized Immigrant AOTC Credit Refund | BN3: Unauthorized Immigrant AOTC Credit Refund | BO3: American Effective Tax AOTC Credit Refund | BP3: Employed Population | BQ3: Authorized Immigrant Employed Population | BR3: Unauthorized Immigrant Employed Population | BS3: American Employed Population | BT3: Average Weekly Hours Worked | BU3: Authorized Immigrant Average Weekly Hours Worked | BV3: Unauthorized Immigrant Average Weekly Hours Worked | BW3: American Average Weekly Hours Worked | BX3: AWHW Min Hours | BY3: AWHW Max Hours | BZ3: Full-Time Employment Rate | CA3: Authorized Immigrant Full-Time Employment Rate | CB3: Unauthorized Immigrant Full-Time Employment Rate | CC3: American Full-Time Employment Rate | CD3: Part-Time Employment Rate | CE3: Authorized Immigrant Part-Time Employment Rate | CF3: Unauthorized Immigrant Part-Time Employment Rate | CG3: American Part-Time Employment Rate | CH3: Job Tenure Average (years) | CI3: Authorized Immigrant Job Tenure Average | CJ3: Unauthorized Immigrant Job Tenure Average | CK3: American Job Tenure Average | CL3: JTA Min Tenure | CM3: JTA Max Tenure | CN3: Turnover Rate | CO3: Authorized Immigrant Turnover Rate | CP3: Unauthorized Immigrant Turnover Rate | CQ3: American Turnover Rate | CR3: Labor Productivity ($/hr) | CS3: Authorized Immigrant Labor Productivity | CT3: Unauthorized Immigrant Labor Productivity | CU3: American Labor Productivity | CV3: Education Level Required Average | CW3: Authorized Immigrant Education Level Average | CX3: Unauthorized Immigrant Education Level Average | CY3: American Education Level Average | CZ3: State/Local Tax Revenue ($) | DA3: Authorized Immigrant State/Local Tax Revenue | DB3: Unauthorized Immigrant State/Local Tax Revenue | DC3: American State/Local Tax Revenue | DD3: Social Security/Medicare Contributions ($) | DE3: Authorized Immigrant Social Security/Medicare Contributions | DF3: Unauthorized Immigrant Social Security/Medicare Contributions | DG3: American Social Security/Medicare Contributions | DH3: Public Assistance Usage Rate | DI3: Authorized Immigrant Public Assistance Usage Rate | DJ3: Unauthorized Immigrant Public Assistance Usage Rate | DK3: American Public Assistance Usage Rate
A4: 0 | B4: All Industries | C4: All Roles | D4: 1444246 | E4: 57770 | F4: 50000 | G4: 1335928 | H4: 0.958 | I4: 1 | J4: 0.9 | K4: 0.958 | L4: 0.59 | M4: 0.619 | N4: 0.678 | O4: 0.59 | P4: 0.042 | Q4: 0 | R4: 0.1 | S4: 0.042 | T4: 0.069 | U4: 0 | V4: 0.18 | W4: 0.069 | X4: 29.76 | Y4: 20 | Z4: 45 | AA4: 54162 | AB4: 36400 | AC4: 81900 | AD4: 27.38 | AE4: 20 | AF4: 40 | AG4: 50305 | AH4: 36400 | AI4: 72800 | AJ4: 23.21 | AK4: 20 | AL4: 35 | AM4: 44076 | AN4: 36400 | AO4: 63700 | AP4: 30.01 | AQ4: 20 | AR4: 45 | AS4: 54658 | AT4: 36400 | AU4: 81900 | AV4: 9248649200 | AW4: 281851851 | AX4: 112742647 | AY4: 8855054870 | AZ4: 11140613983 | BA4: 384096166 | BB4: 117038194 | BC4: 10637471623 | BD4: 150000000 | BE4: 135000000 | BF4: 0 | BG4: 15000000 | BH4: 120000000 | BI4: 30000000 | BJ4: 60000000 | BK4: 30000000 | BL4: 80000000 | BM4: 20000000 | BN4: 4000000 | BO4: 56000000 | BP4: 1399400 | BQ4: 57770 | BR4: 45000 | BS4: 1294574 | BT4: 35.1 | BU4: 35.7 | BV4: 36.75 | BW4: 34.96 | BX4: 20 | BY4: 50 | BZ4: 0.68 | CA4: 0.68 | CB4: 0.72 | CC4: 0.68 | CD4: 0.32 | CE4: 0.32 | CF4: 0.28 | CG4: 0.32 | CH4: 4.5 | CI4: 4 | CJ4: 3.2 | CK4: 4.6 | CL4: 1 | CM4: 10 | CN4: 0.45 | CO4: 0.5 | CP4: 0.63 | CQ4: 0.44 | CR4: 65 | CS4: 61.75 | CT4: 58.16 | CU4: 65.45 | CV4: 3 | CW4: 2.7 | CX4: 2.2 | CY4: 3.1 | CZ4: 924864920 | DA4: 281851851 | DB4: 112742647 | DC4: 885505487 | DD4: 11140613983 | DE4: 384096166 | DF4: 117038194 | DG4: 10637471623 | DH4: 0.12 | DI4: 0.08 | DJ4: 0.06 | DK4: 0.13
A5: 1 | B5: Agriculture | C5: Worker | D5: 28319 | E5: 1133 | F5: 1962 | G5: 23788 | H5: 0.958 | I5: 0.98 | J5: 0.85 | K5: 0.958 | L5: 0.012 | M5: 0.619 | N5: 0.678 | O5: 0.011 | P5: 0.042 | Q5: 0.02 | R5: 0.15 | S5: 0.042 | T5: 0.069 | U5: 0.033 | V5: 0.27 | W5: 0.069 | X5: 25.5 | Y5: 20 | Z5: 35 | AA5: 55860 | AB5: 43680 | AC5: 76440 | AD5: 24.99 | AE5: 20 | AF5: 34.3 | AG5: 54708 | AH5: 43680 | AI5: 74874 | AJ5: 21.68 | AK5: 20 | AL5: 29.75 | AM5: 47500 | AN5: 43680 | AO5: 64938 | AP5: 25.5 | AQ5: 20 | AR5: 35 | AS5: 55860 | AT5: 43680 | AU5: 76440 | AV5: 181200000 | AW5: 6000000 | AX5: 2400000 | AY5: 172800000 | AZ5: 218000000 | BA5: 7200000 | BB5: 2200000 | BC5: 208600000 | BD5: 5000000 | BE5: 4500000 | BF5: 0 | BG5: 500000 | BH5: 4000000 | BI5: 1000000 | BJ5: 2000000 | BK5: 1000000 | BL5: 3000000 | BM5: 750000 | BN5: 150000 | BO5: 2100000 | BP5: 27140 | BQ5: 1140 | BR5: 1840 | BS5: 24160 | BT5: 42 | BU5: 42.8 | BV5: 44.1 | BW5: 41.8 | BX5: 30 | BY5: 55 | BZ5: 0.85 | CA5: 0.88 | CB5: 0.9 | CC5: 0.84 | CD5: 0.15 | CE5: 0.12 | CF5: 0.1 | CG5: 0.16 | CH5: 3.8 | CI5: 3.5 | CJ5: 2.8 | CK5: 3.9 | CL5: 1 | CM5: 8 | CN5: 0.55 | CO5: 0.6 | CP5: 0.7 | CQ5: 0.54 | CR5: 55 | CS5: 52.25 | CT5: 49.2 | CU5: 55.9 | CV5: 2.8 | CW5: 2.5 | CX5: 2 | CY5: 2.9 | CZ5: 18120000 | DA5: 6000000 | DB5: 2400000 | DC5: 17280000 | DD5: 218000000 | DE5: 7200000 | DF5: 2200000 | DG5: 208600000 | DH5: 0.25 | DI5: 0.18 | DJ5: 0.15 | DK5: 0.26 | HW5: 0.1
A6: 2 | B6: Agriculture | C6: Support | D6: 7080 | E6: 283 | F6: 491 | G6: 5947 | H6: 0.958 | I6: 0.98 | J6: 0.85 | K6: 0.958 | L6: 0.003 | M6: 0.619 | N6: 0.678 | O6: 0.003 | P6: 0.042 | Q6: 0.02 | R6: 0.15 | S6: 0.042 | T6: 0.069 | U6: 0.033 | V6: 0.27 | W6: 0.069 | X6: 25.5 | Y6: 20 | Z6: 35 | AA6: 55860 | AB6: 43680 | AC6: 76440 | AD6: 24.99 | AE6: 20 | AF6: 34.3 | AG6: 54708 | AH6: 43680 | AI6: 74874 | AJ6: 21.68 | AK6: 20 | AL6: 29.75 | AM6: 47500 | AN6: 43680 | AO6: 64938 | AP6: 25.5 | AQ6: 20 | AR6: 35 | AS6: 55860 | AT6: 43680 | AU6: 76440 | AV6: 45300000 | AW6: 1500000 | AX6: 600000 | AY6: 43200000 | AZ6: 54500000 | BA6: 1800000 | BB6: 550000 | BC6: 52150000 | BD6: 1250000 | BE6: 1125000 | BF6: 0 | BG6: 125000 | BH6: 1000000 | BI6: 250000 | BJ6: 500000 | BK6: 250000 | BL6: 750000 | BM6: 187500 | BN6: 37500 | BO6: 525000 | BP6: 6785 | BQ6: 285 | BR6: 460 | BS6: 6040 | BT6: 42 | BU6: 42.8 | BV6: 44.1 | BW6: 41.8 | BX6: 30 | BY6: 55 | BZ6: 0.85 | CA6: 0.88 | CB6: 0.9 | CC6: 0.84 | CD6: 0.15 | CE6: 0.12 | CF6: 0.1 | CG6: 0.16 | CH6: 3.8 | CI6: 3.5 | CJ6: 2.8 | CK6: 3.9 | CL6: 1 | CM6: 8 | CN6: 0.55 | CO6: 0.6 | CP6: 0.7 | CQ6: 0.54 | CR6: 55 | CS6: 52.25 | CT6: 49.2 | CU6: 55.9 | CV6: 2.8 | CW6: 2.5 | CX6: 2 | CY6: 2.9 | CZ6: 4530000 | DA6: 1500000 | DB6: 600000 | DC6: 4320000 | DD6: 54500000 | DE6: 1800000 | DF6: 550000 | DG6: 52150000 | DH6: 0.25 | DI6: 0.18 | DJ6: 0.15 | DK6: 0.26
A7: 3 | B7: Construction | C7: Worker | D7: 55363 | E7: 2215 | F7: 5754 | G7: 43183 | H7: 0.958 | I7: 0.98 | J7: 0.88 | K7: 0.958 | L7: 0.023 | M7: 0.619 | N7: 0.712 | O7: 0.02 | P7: 0.042 | Q7: 0.02 | R7: 0.12 | S7: 0.042 | T7: 0.069 | U7: 0.033 | V7: 0.216 | W7: 0.069 | X7: 32.5 | Y7: 22 | Z7: 50 | AA7: 70200 | AB7: 47520 | AC7: 108000 | AD7: 31.85 | AE7: 22 | AF7: 45 | AG7: 68932 | AH7: 47520 | AI7: 97200 | AJ7: 28.6 | AK7: 22 | AL7: 40.5 | AM7: 61776 | AN7: 47520 | AO7: 87480 | AP7: 32.5 | AQ7: 22 | AR7: 50 | AS7: 70200 | AT7: 47520 | AU7: 108000 | AV7: 372000000 | AW7: 12800000 | AX7: 5120000 | AY7: 354080000 | AZ7: 447600000 | BA7: 17280000 | BB7: 5268000 | BC7: 425088000 | BD7: 12000000 | BE7: 10800000 | BF7: 0 | BG7: 1200000 | BH7: 9600000 | BI7: 2400000 | BJ7: 4800000 | BK7: 2400000 | BL7: 7200000 | BM7: 1800000 | BN7: 360000 | BO7: 5040000 | BP7: 53050 | BQ7: 2228 | BR7: 5390 | BS7: 45432 | BT7: 39.5 | BU7: 40.2 | BV7: 41.5 | BW7: 39 | BX7: 25 | BY7: 60 | BZ7: 0.82 | CA7: 0.85 | CB7: 0.88 | CC7: 0.81 | CD7: 0.18 | CE7: 0.15 | CF7: 0.12 | CG7: 0.19 | CH7: 4.2 | CI7: 3.8 | CJ7: 3 | CK7: 4.3 | CL7: 1 | CM7: 9 | CN7: 0.5 | CO7: 0.55 | CP7: 0.65 | CQ7: 0.49 | CR7: 75 | CS7: 71.25 | CT7: 67.1 | CU7: 75.9 | CV7: 3.5 | CW7: 3.2 | CX7: 2.5 | CY7: 3.6 | CZ7: 37200000 | DA7: 12800000 | DB7: 5120000 | DC7: 35408000 | DD7: 447600000 | DE7: 17280000 | DF7: 5268000 | DG7: 425088000 | DH7: 0.15 | DI7: 0.1 | DJ7: 0.08 | DK7: 0.16
A8: 4 | B8: Construction | C8: Support | D8: 13841 | E8: 554 | F8: 1439 | G8: 10796 | H8: 0.958 | I8: 0.98 | J8: 0.88 | K8: 0.958 | L8: 0.006 | M8: 0.619 | N8: 0.712 | O8: 0.005 | P8: 0.042 | Q8: 0.02 | R8: 0.12 | S8: 0.042 | T8: 0.069 | U8: 0.033 | V8: 0.216 | W8: 0.069 | X8: 32.5 | Y8: 22 | Z8: 50 | AA8: 70200 | AB8: 47520 | AC8: 108000 | AD8: 31.85 | AE8: 22 | AF8: 45 | AG8: 68932 | AH8: 47520 | AI8: 97200 | AJ8: 28.6 | AK8: 22 | AL8: 40.5 | AM8: 61776 | AN8: 47520 | AO8: 87480 | AP8: 32.5 | AQ8: 22 | AR8: 50 | AS8: 70200 | AT8: 47520 | AU8: 108000 | AV8: 93000000 | AW8: 3200000 | AX8: 1280000 | AY8: 88520000 | AZ8: 111900000 | BA8: 4320000 | BB8: 1317000 | BC8: 106272000 | BD8: 3000000 | BE8: 2700000 | BF8: 0 | BG8: 300000 | BH8: 2400000 | BI8: 600000 | BJ8: 1200000 | BK8: 600000 | BL8: 1800000 | BM8: 450000 | BN8: 90000 | BO8: 1260000 | BP8: 13262 | BQ8: 558 | BR8: 1348 | BS8: 11356 | BT8: 39.5 | BU8: 40.2 | BV8: 41.5 | BW8: 39 | BX8: 25 | BY8: 60 | BZ8: 0.82 | CA8: 0.85 | CB8: 0.88 | CC8: 0.81 | CD8: 0.18 | CE8: 0.15 | CF8: 0.12 | CG8: 0.19 | CH8: 4.2 | CI8: 3.8 | CJ8: 3 | CK8: 4.3 | CL8: 1 | CM8: 9 | CN8: 0.5 | CO8: 0.55 | CP8: 0.65 | CQ8: 0.49 | CR8: 75 | CS8: 71.25 | CT8: 67.1 | CU8: 75.9 | CV8: 3.5 | CW8: 3.2 | CX8: 2.5 | CY8: 3.6 | CZ8: 9300000 | DA8: 3200000 | DB8: 1280000 | DC8: 8852000 | DD8: 111900000 | DE8: 4320000 | DF8: 1317000 | DG8: 106272000 | DH8: 0.15 | DI8: 0.1 | DJ8: 0.08 | DK8: 0.16
A9: 5 | B9: Hospitality | C9: Worker | D9: 119700 | E9: 4788 | F9: 9576 | G9: 99336 | H9: 0.958 | I9: 0.98 | J9: 0.9 | K9: 0.958 | L9: 0.049 | M9: 0.619 | N9: 0.678 | O9: 0.046 | P9: 0.042 | Q9: 0.02 | R9: 0.1 | S9: 0.042 | T9: 0.069 | U9: 0.033 | V9: 0.18 | W9: 0.069 | X9: 18.5 | Y9: 12 | Z9: 28 | AA9: 39960 | AB9: 25920 | AC9: 60480 | AD9: 18.13 | AE9: 12 | AF9: 27.44 | AG9: 39161 | AH9: 25920 | AI9: 59078 | AJ9: 15.73 | AK9: 12 | AL9: 23.8 | AM9: 33974 | AN9: 25920 | AO9: 51336 | AP9: 18.5 | AQ9: 12 | AR9: 28 | AS9: 39960 | AT9: 25920 | AU9: 60480 | AV9: 460000000 | AW9: 15840000 | AX9: 6336000 | AY9: 437776000 | AZ9: 553600000 | BA9: 21384000 | BB9: 6520800 | BC9: 525696000 | BD9: 30000000 | BE9: 27000000 | BF9: 0 | BG9: 3000000 | BH9: 24000000 | BI9: 6000000 | BJ9: 12000000 | BK9: 6000000 | BL9: 18000000 | BM9: 4500000 | BN9: 900000 | BO9: 12600000 | BP9: 114700 | BQ9: 4815 | BR9: 8970 | BS9: 100915 | BT9: 28.5 | BU9: 29 | BV9: 30 | BW9: 28.2 | BX9: 15 | BY9: 45 | BZ9: 0.45 | CA9: 0.48 | CB9: 0.55 | CC9: 0.44 | CD9: 0.55 | CE9: 0.52 | CF9: 0.45 | CG9: 0.56 | CH9: 3.2 | CI9: 2.9 | CJ9: 2.3 | CK9: 3.3 | CL9: 0.5 | CM9: 7 | CN9: 0.65 | CO9: 0.7 | CP9: 0.8 | CQ9: 0.64 | CR9: 40 | CS9: 38 | CT9: 35.8 | CU9: 40.5 | CV9: 2.2 | CW9: 2 | CX9: 1.6 | CY9: 2.3 | CZ9: 46000000 | DA9: 15840000 | DB9: 6336000 | DC9: 43776000 | DD9: 553600000 | DE9: 21384000 | DF9: 6520800 | DG9: 525696000 | DH9: 0.28 | DI9: 0.22 | DJ9: 0.18 | DK9: 0.29
A10: 6 | B10: Hospitality | C10: Support | D10: 29925 | E10: 1197 | F10: 2394 | G10: 24834 | H10: 0.958 | I10: 0.98 | J10: 0.9 | K10: 0.958 | L10: 0.012 | M10: 0.619 | N10: 0.678 | O10: 0.011 | P10: 0.042 | Q10: 0.02 | R10: 0.1 | S10: 0.042 | T10: 0.069 | U10: 0.033 | V10: 0.18 | W10: 0.069 | X10: 18.5 | Y10: 12 | Z10: 28 | AA10: 39960 | AB10: 25920 | AC10: 60480 | AD10: 18.13 | AE10: 12 | AF10: 27.44 | AG10: 39161 | AH10: 25920 | AI10: 59078 | AJ10: 15.73 | AK10: 12 | AL10: 23.8 | AM10: 33974 | AN10: 25920 | AO10: 51336 | AP10: 18.5 | AQ10: 12 | AR10: 28 | AS10: 39960 | AT10: 25920 | AU10: 60480 | AV10: 115000000 | AW10: 3960000 | AX10: 1584000 | AY10: 109444000 | AZ10: 138400000 | BA10: 5346000 | BB10: 1630200 | BC10: 131424000 | BD10: 7500000 | BE10: 6750000 | BF10: 0 | BG10: 750000 | BH10: 6000000 | BI10: 1500000 | BJ10: 3000000 | BK10: 1500000 | BL10: 4500000 | BM10: 1125000 | BN10: 225000 | BO10: 3150000 | BP10: 28675 | BQ10: 1204 | BR10: 2242 | BS10: 25229 | BT10: 28.5 | BU10: 29 | BV10: 30 | BW10: 28.2 | BX10: 15 | BY10: 45 | BZ10: 0.45 | CA10: 0.48 | CB10: 0.55 | CC10: 0.44 | CD10: 0.55 | CE10: 0.52 | CF10: 0.45 | CG10: 0.56 | CH10: 3.2 | CI10: 2.9 | CJ10: 2.3 | CK10: 3.3 | CL10: 0.5 | CM10: 7 | CN10: 0.65 | CO10: 0.7 | CP10: 0.8 | CQ10: 0.64 | CR10: 40 | CS10: 38 | CT10: 35.8 | CU10: 40.5 | CV10: 2.2 | CW10: 2 | CX10: 1.6 | CY10: 2.3 | CZ10: 11500000 | DA10: 3960000 | DB10: 1584000 | DC10: 10944000 | DD10: 138400000 | DE10: 5346000 | DF10: 1630200 | DG10: 131424000 | DH10: 0.28 | DI10: 0.22 | DJ10: 0.18 | DK10: 0.29
A11: 7 | B11: Cleaning & Maintenance | C11: Worker | D11: 42500 | E11: 1700 | F11: 4250 | G11: 36550 | H11: 0.958 | I11: 0.98 | J11: 0.9 | K11: 0.958 | L11: 0.017 | M11: 0.619 | N11: 0.678 | O11: 0.016 | P11: 0.042 | Q11: 0.02 | R11: 0.1 | S11: 0.042 | T11: 0.069 | U11: 0.033 | V11: 0.18 | W11: 0.069 | X11: 22 | Y11: 15 | Z11: 32 | AA11: 47520 | AB11: 32400 | AC11: 69120 | AD11: 21.56 | AE11: 15 | AF11: 31.36 | AG11: 46570 | AH11: 32400 | AI11: 67678 | AJ11: 18.7 | AK11: 15 | AL11: 27.2 | AM11: 40392 | AN11: 32400 | AO11: 58784 | AP11: 22 | AQ11: 15 | AR11: 32 | AS11: 47520 | AT11: 32400 | AU11: 69120 | AV11: 195000000 | AW11: 6720000 | AX11: 2688000 | AY11: 185592000 | AZ11: 234600000 | BA11: 9054000 | BB11: 2763000 | BC11: 222783000 | BD11: 8500000 | BE11: 7650000 | BF11: 0 | BG11: 850000 | BH11: 6800000 | BI11: 1700000 | BJ11: 3400000 | BK11: 1700000 | BL11: 5100000 | BM11: 1275000 | BN11: 255000 | BO11: 3570000 | BP11: 40700 | BQ11: 1710 | BR11: 3980 | BS11: 35010 | BT11: 38 | BU11: 38.7 | BV11: 40 | BW11: 37.8 | BX11: 20 | BY11: 50 | BZ11: 0.62 | CA11: 0.65 | CB11: 0.7 | CC11: 0.61 | CD11: 0.38 | CE11: 0.35 | CF11: 0.3 | CG11: 0.39 | CH11: 3.5 | CI11: 3.2 | CJ11: 2.5 | CK11: 3.6 | CL11: 0.8 | CM11: 8 | CN11: 0.58 | CO11: 0.63 | CP11: 0.75 | CQ11: 0.57 | CR11: 50 | CS11: 47.5 | CT11: 44.7 | CU11: 50.6 | CV11: 2.5 | CW11: 2.3 | CX11: 1.8 | CY11: 2.6 | CZ11: 19500000 | DA11: 6720000 | DB11: 2688000 | DC11: 18559200 | DD11: 234600000 | DE11: 9054000 | DF11: 2763000 | DG11: 222783000 | DH11: 0.22 | DI11: 0.16 | DJ11: 0.13 | DK11: 0.23
A12: 8 | B12: Cleaning & Maintenance | C12: Support | D12: 10625 | E12: 425 | F12: 1063 | G12: 9138 | H12: 0.958 | I12: 0.98 | J12: 0.9 | K12: 0.958 | L12: 0.004 | M12: 0.619 | N12: 0.678 | O12: 0.004 | P12: 0.042 | Q12: 0.02 | R12: 0.1 | S12: 0.042 | T12: 0.069 | U12: 0.033 | V12: 0.18 | W12: 0.069 | X12: 22 | Y12: 15 | Z12: 32 | AA12: 47520 | AB12: 32400 | AC12: 69120 | AD12: 21.56 | AE12: 15 | AF12: 31.36 | AG12: 46570 | AH12: 32400 | AI12: 67678 | AJ12: 18.7 | AK12: 15 | AL12: 27.2 | AM12: 40392 | AN12: 32400 | AO12: 58784 | AP12: 22 | AQ12: 15 | AR12: 32 | AS12: 47520 | AT12: 32400 | AU12: 69120 | AV12: 48750000 | AW12: 1680000 | AX12: 672000 | AY12: 46398000 | AZ12: 58650000 | BA12: 2263500 | BB12: 690750 | BC12: 55695750 | BD12: 2125000 | BE12: 1912500 | BF12: 0 | BG12: 212500 | BH12: 1700000 | BI12: 425000 | BJ12: 850000 | BK12: 425000 | BL12: 1275000 | BM12: 318750 | BN12: 63750 | BO12: 892500 | BP12: 10175 | BQ12: 428 | BR12: 995 | BS12: 8752 | BT12: 38 | BU12: 38.7 | BV12: 40 | BW12: 37.8 | BX12: 20 | BY12: 50 | BZ12: 0.62 | CA12: 0.65 | CB12: 0.7 | CC12: 0.61 | CD12: 0.38 | CE12: 0.35 | CF12: 0.3 | CG12: 0.39 | CH12: 3.5 | CI12: 3.2 | CJ12: 2.5 | CK12: 3.6 | CL12: 0.8 | CM12: 8 | CN12: 0.58 | CO12: 0.63 | CP12: 0.75 | CQ12: 0.57 | CR12: 50 | CS12: 47.5 | CT12: 44.7 | CU12: 50.6 | CV12: 2.5 | CW12: 2.3 | CX12: 1.8 | CY12: 2.6 | CZ12: 4875000 | DA12: 1680000 | DB12: 672000 | DC12: 4639800 | DD12: 58650000 | DE12: 2263500 | DF12: 690750 | DG12: 55695750 | DH12: 0.22 | DI12: 0.16 | DJ12: 0.13 | DK12: 0.23
A13: 9 | B13: Manufacturing | C13: Worker | D13: 149040 | E13: 5962 | F13: 11924 | G13: 131154 | H13: 0.958 | I13: 1.02 | J13: 0.92 | K13: 0.958 | L13: 0.061 | M13: 0.681 | N13: 0.712 | O13: 0.058 | P13: 0.042 | Q13: 0 | R13: 0.08 | S13: 0.042 | T13: 0.069 | U13: 0 | V13: 0.144 | W13: 0.069 | X13: 28.5 | Y13: 20 | Z13: 40 | AA13: 61560 | AB13: 43200 | AC13: 86400 | AD13: 26.25 | AE13: 20 | AF13: 37 | AG13: 56700 | AH13: 43200 | AI13: 79920 | AJ13: 23.5 | AK13: 20 | AL13: 32 | AM13: 50760 | AN13: 43200 | AO13: 69120 | AP13: 28.5 | AQ13: 20 | AR13: 40 | AS13: 61560 | AT13: 43200 | AU13: 86400 | AV13: 885000000 | AW13: 30450000 | AX13: 12180000 | AY13: 842070000 | AZ13: 1065000000 | BA13: 41085000 | BB13: 12523500 | BC13: 1012561500 | BD13: 40000000 | BE13: 36000000 | BF13: 0 | BG13: 4000000 | BH13: 32000000 | BI13: 8000000 | BJ13: 16000000 | BK13: 8000000 | BL13: 24000000 | BM13: 6000000 | BN13: 1200000 | BO13: 16800000 | BP13: 142800 | BQ13: 6000 | BR13: 11180 | BS13: 125620 | BT13: 41.2 | BU13: 42 | BV13: 43.2 | BW13: 41 | BX13: 30 | BY13: 55 | BZ13: 0.78 | CA13: 0.8 | CB13: 0.85 | CC13: 0.77 | CD13: 0.22 | CE13: 0.2 | CF13: 0.15 | CG13: 0.23 | CH13: 5 | CI13: 4.5 | CJ13: 3.6 | CK13: 5.1 | CL13: 1.5 | CM13: 10 | CN13: 0.4 | CO13: 0.45 | CP13: 0.55 | CQ13: 0.39 | CR13: 70 | CS13: 66.5 | CT13: 62.6 | CU13: 70.8 | CV13: 3.8 | CW13: 3.5 | CX13: 2.8 | CY13: 3.9 | CZ13: 88500000 | DA13: 30450000 | DB13: 12180000 | DC13: 84207000 | DD13: 1065000000 | DE13: 41085000 | DF13: 12523500 | DG13: 1012561500 | DH13: 0.1 | DI13: 0.07 | DJ13: 0.05 | DK13: 0.11
A14: 10 | B14: Manufacturing | C14: Support | D14: 37921 | E14: 1517 | F14: 5309 | G14: 31095 | H14: 0.958 | I14: 1.02 | J14: 0.92 | K14: 0.958 | L14: 0.015 | M14: 0.681 | N14: 0.712 | O14: 0.014 | P14: 0.042 | Q14: 0 | R14: 0.08 | S14: 0.042 | T14: 0.069 | U14: 0 | V14: 0.144 | W14: 0.069 | X14: 28.5 | Y14: 20 | Z14: 40 | AA14: 61560 | AB14: 43200 | AC14: 86400 | AD14: 26.25 | AE14: 20 | AF14: 37 | AG14: 56700 | AH14: 43200 | AI14: 79920 | AJ14: 23.5 | AK14: 20 | AL14: 32 | AM14: 50760 | AN14: 43200 | AO14: 69120 | AP14: 28.5 | AQ14: 20 | AR14: 40 | AS14: 61560 | AT14: 43200 | AU14: 86400 | AV14: 240094933 | AW14: 11707 | AX14: 14341 | AY14: 174361875 | AZ14: 289210339 | BA14: 15954 | BB14: 14888 | BC14: 209458837 | BD14: 3894000 | BE14: 5607 | BF14: 0 | BG14: 295360 | BH14: 3115200 | BI14: 1246 | BJ14: 3816 | BK14: 590720 | BL14: 2076800 | BM14: 831 | BN14: 153 | BO14: 1102677 | BP14: 36328 | BQ14: 1453 | BR14: 5086 | BS14: 29789 | BT14: 41.2 | BU14: 42 | BV14: 43.2 | BW14: 41 | BX14: 30 | BY14: 55 | BZ14: 0.78 | CA14: 0.8 | CB14: 0.85 | CC14: 0.77 | CD14: 0.22 | CE14: 0.2 | CF14: 0.15 | CG14: 0.23 | CH14: 5 | CI14: 4.5 | CJ14: 3.6 | CK14: 5.1 | CL14: 1.5 | CM14: 10 | CN14: 0.4 | CO14: 0.45 | CP14: 0.55 | CQ14: 0.39 | CR14: 70 | CS14: 66.5 | CT14: 62.6 | CU14: 70.8 | CV14: 3.8 | CW14: 3.5 | CX14: 2.8 | CY14: 3.9 | CZ14: 240094933 | DA14: 11707 | DB14: 12620 | DC14: 174361875 | DD14: 578420678 | DE14: 31908 | DF14: 19354 | DG14: 418917674 | DH14: 0.1 | DI14: 0.07 | DJ14: 0.05 | DK14: 0.11
A15: 11 | B15: Transportation & Warehousing | C15: Worker | D15: 109556 | E15: 4382 | F15: 10956 | G15: 94218 | H15: 0.958 | I15: 1.02 | J15: 0.9 | K15: 0.958 | L15: 0.045 | M15: 0.681 | N15: 0.678 | O15: 0.042 | P15: 0.042 | Q15: 0 | R15: 0.1 | S15: 0.042 | T15: 0.069 | U15: 0.033 | V15: 0.18 | W15: 0.069 | X15: 30 | Y15: 22 | Z15: 45 | AA15: 64800 | AB15: 47520 | AC15: 97200 | AD15: 27.6 | AE15: 22 | AF15: 41.4 | AG15: 59616 | AH15: 47520 | AI15: 89424 | AJ15: 24.75 | AK15: 22 | AL15: 37.13 | AM15: 53460 | AN15: 47520 | AO15: 80190 | AP15: 30.5 | AQ15: 22 | AR15: 45 | AS15: 65880 | AT15: 47520 | AU15: 97200 | AV15: 780000000 | AW15: 26880000 | AX15: 10752000 | AY15: 742368000 | AZ15: 936000000 | BA15: 36288000 | BB15: 11059200 | BC15: 888652800 | BD15: 28000000 | BE15: 25200000 | BF15: 0 | BG15: 2800000 | BH15: 22400000 | BI15: 5600000 | BJ15: 11200000 | BK15: 5600000 | BL15: 16800000 | BM15: 4200000 | BN15: 840000 | BO15: 11760000 | BP15: 104900 | BQ15: 4382 | BR15: 9860 | BS15: 90658 | BT15: 40.5 | BU15: 41.3 | BV15: 42.5 | BW15: 40.2 | BX15: 25 | BY15: 60 | BZ15: 0.75 | CA15: 0.78 | CB15: 0.82 | CC15: 0.74 | CD15: 0.25 | CE15: 0.22 | CF15: 0.18 | CG15: 0.26 | CH15: 4.8 | CI15: 4.3 | CJ15: 3.4 | CK15: 4.9 | CL15: 1 | CM15: 9 | CN15: 0.42 | CO15: 0.47 | CP15: 0.58 | CQ15: 0.41 | CR15: 82 | CS15: 77.9 | CT15: 73.4 | CU15: 83 | CV15: 3.4 | CW15: 3.1 | CX15: 2.5 | CY15: 3.5 | CZ15: 78000000 | DA15: 26880000 | DB15: 10752000 | DC15: 74236800 | DD15: 936000000 | DE15: 36288000 | DF15: 11059200 | DG15: 888652800 | DH15: 0.14 | DI15: 0.1 | DJ15: 0.07 | DK15: 0.15
A16: 12 | B16: Transportation & Warehousing | C16: Support | D16: 36519 | E16: 1461 | F16: 3652 | G16: 31406 | H16: 0.958 | I16: 1.02 | J16: 0.9 | K16: 0.958 | L16: 0.015 | M16: 0.681 | N16: 0.678 | O16: 0.014 | P16: 0.042 | Q16: 0 | R16: 0.1 | S16: 0.042 | T16: 0.069 | U16: 0.033 | V16: 0.18 | W16: 0.069 | X16: 30 | Y16: 22 | Z16: 45 | AA16: 64800 | AB16: 47520 | AC16: 97200 | AD16: 27.6 | AE16: 22 | AF16: 41.4 | AG16: 59616 | AH16: 47520 | AI16: 89424 | AJ16: 24.75 | AK16: 22 | AL16: 37.13 | AM16: 53460 | AN16: 47520 | AO16: 80190 | AP16: 30.5 | AQ16: 22 | AR16: 45 | AS16: 65880 | AT16: 47520 | AU16: 97200 | AV16: 260000000 | AW16: 8960000 | AX16: 3584000 | AY16: 247456000 | AZ16: 312000000 | BA16: 12096000 | BB16: 3686400 | BC16: 296217600 | BD16: 9333333 | BE16: 8400000 | BF16: 0 | BG16: 933333 | BH16: 7466667 | BI16: 1866667 | BJ16: 3733333 | BK16: 1866667 | BL16: 5600000 | BM16: 1400000 | BN16: 280000 | BO16: 3920000 | BP16: 34967 | BQ16: 1461 | BR16: 3287 | BS16: 30219 | BT16: 40.5 | BU16: 41.3 | BV16: 42.5 | BW16: 40.2 | BX16: 25 | BY16: 60 | BZ16: 0.75 | CA16: 0.78 | CB16: 0.82 | CC16: 0.74 | CD16: 0.25 | CE16: 0.22 | CF16: 0.18 | CG16: 0.26 | CH16: 4.8 | CI16: 4.3 | CJ16: 3.4 | CK16: 4.9 | CL16: 1 | CM16: 9 | CN16: 0.42 | CO16: 0.47 | CP16: 0.58 | CQ16: 0.41 | CR16: 82 | CS16: 77.9 | CT16: 73.4 | CU16: 83 | CV16: 3.4 | CW16: 3.1 | CX16: 2.5 | CY16: 3.5 | CZ16: 26000000 | DA16: 8960000 | DB16: 3584000 | DC16: 24745600 | DD16: 312000000 | DE16: 12096000 | DF16: 3686400 | DG16: 296217600 | DH16: 0.14 | DI16: 0.1 | DJ16: 0.07 | DK16: 0.15
A17: 13 | B17: Retail Trade | C17: Worker | D17: 122703 | E17: 4908 | F17: 9816 | G17: 107979 | H17: 0.958 | I17: 1 | J17: 0.9 | K17: 0.958 | L17: 0.05 | M17: 0.619 | N17: 0.678 | O17: 0.047 | P17: 0.042 | Q17: 0 | R17: 0.1 | S17: 0.042 | T17: 0.069 | U17: 0.033 | V17: 0.18 | W17: 0.069 | X17: 20.5 | Y17: 15 | Z17: 30 | AA17: 44280 | AB17: 32400 | AC17: 64800 | AD17: 19.49 | AE17: 15 | AF17: 28.44 | AG17: 42100 | AH17: 32400 | AI17: 61345 | AJ17: 16.91 | AK17: 15 | AL17: 24.7 | AM17: 36500 | AN17: 32400 | AO17: 53275 | AP17: 20.5 | AQ17: 15 | AR17: 30 | AS17: 44280 | AT17: 32400 | AU17: 64800 | AV17: 1040000000 | AW17: 35840000 | AX17: 14336000 | AY17: 989760000 | AZ17: 1248000000 | BA17: 48288000 | BB17: 14726400 | BC17: 1184985600 | BD17: 60000000 | BE17: 54000000 | BF17: 0 | BG17: 6000000 | BH17: 48000000 | BI17: 12000000 | BJ17: 24000000 | BK17: 12000000 | BL17: 36000000 | BM17: 9000000 | BN17: 1800000 | BO17: 25200000 | BP17: 117600 | BQ17: 4908 | BR17: 8834 | BS17: 103858 | BT17: 32 | BU17: 32.6 | BV17: 33.6 | BW17: 31.8 | BX17: 15 | BY17: 45 | BZ17: 0.55 | CA17: 0.58 | CB17: 0.65 | CC17: 0.54 | CD17: 0.45 | CE17: 0.42 | CF17: 0.35 | CG17: 0.46 | CH17: 3.9 | CI17: 3.5 | CJ17: 2.8 | CK17: 4 | CL17: 0.8 | CM17: 8 | CN17: 0.48 | CO17: 0.53 | CP17: 0.63 | CQ17: 0.47 | CR17: 48 | CS17: 45.6 | CT17: 42.9 | CU17: 48.6 | CV17: 2.6 | CW17: 2.4 | CX17: 1.9 | CY17: 2.7 | CZ17: 104000000 | DA17: 35840000 | DB17: 14336000 | DC17: 98976000 | DD17: 1248000000 | DE17: 48288000 | DF17: 14726400 | DG17: 1184985600 | DH17: 0.2 | DI17: 0.15 | DJ17: 0.12 | DK17: 0.21
... A56: 52 | B56: Public Administration | C56: Worker | D56: 85000 | E56: 3400 | F56: 6800 | G56: 74800 | H56: 0.958 | I56: 1.02 | J56: 0.92 | K56: 0.958 | L56: 0.035 | M56: 0.681 | N56: 0.712 | O56: 0.033 | P56: 0.042 | Q56: 0 | R56: 0.08 | S56: 0.042 | T56: 0.069 | U56: 0 | V56: 0.144 | W56: 0.069 | X56: 35 | Y56: 28 | Z56: 50 | AA56: 75600 | AB56: 60480 | AC56: 108000 | AD56: 32.2 | AE56: 28 | AF56: 48.3 | AG56: 69552 | AH56: 60480 | AI56: 104328 | AJ56: 28.8 | AK56: 28 | AL56: 43.2 | AM56: 62208 | AN56: 60480 | AO56: 93312 | AP56: 35.5 | AQ56: 28 | AR56: 50 | AS56: 76680 | AT56: 60480 | AU56: 108000 | AV56: 600000000 | AW56: 20640000 | AX56: 8256000 | AY56: 570984000 | AZ56: 722000000 | BA56: 27888000 | BB56: 8500800 | BC56: 686131200 | BD56: 20000000 | BE56: 18000000 | BF56: 0 | BG56: 2000000 | BH56: 16000000 | BI56: 4000000 | BJ56: 8000000 | BK56: 4000000 | BL56: 12000000 | BM56: 3000000 | BN56: 600000 | BO56: 8400000 | BP56: 81380 | BQ56: 3400 | BR56: 6370 | BS56: 71644 | BT56: 38.5 | BU56: 39.2 | BV56: 40.5 | BW56: 38.3 | BX56: 25 | BY56: 55 | BZ56: 0.85 | CA56: 0.87 | CB56: 0.9 | CC56: 0.84 | CD56: 0.15 | CE56: 0.13 | CF56: 0.1 | CG56: 0.16 | CH56: 6.5 | CI56: 5.9 | CJ56: 4.8 | CK56: 6.6 | CL56: 1.5 | CM56: 12 | CN56: 0.28 | CO56: 0.33 | CP56: 0.43 | CQ56: 0.27 | CR56: 90 | CS56: 85.5 | CT56: 80.5 | CU56: 91.2 | CV56: 4.5 | CW56: 4.2 | CX56: 3.4 | CY56: 4.6 | CZ56: 60000000 | DA56: 20640000 | DB56: 8256000 | DC56: 570984000 | DD56: 722000000 | DE56: 27888000 | DF56: 8500800 | DG56: 686131200 | DH56: 0.07 | DI56: 0.05 | DJ56: 0.03 | DK56: 0.08

Sheet VALID
A1: LSD.RID.0.AR.VALID | B1: Arkansas Labor Statistic Calculation Validation | C1: December 2025
A2: VALID | B2: Metric | C2: Calculated Value | D2: Public Value | E2: Source | F2: Validation Rating | G2: Notes/Improvement
A3: AR.VALID.0 | B3: Labor Force Population (Total) | C3: 1444246 | D3: 1444246 | E3: BLS LAUS Dec 2025 | F3: High | G3: Exact match to seasonally adjusted civilian labor force.
A4: AR.VALID.1 | B4: Unauthorized Labor Force Population | C4: 50000 | D4: ~47000–55000 | E4: MPI 2023 est. adjusted to 2025 | F4: Medium | G4: Reasonable cap; MPI ~47k employed, ~50k LF plausible for AR small unauthorized population.
A5: AR.VALID.2 | B5: Authorized Labor Force Population | C5: 57770 | D5: N/A | E5: Derived from shares | F5: Medium | G5: Consistent with AUTH_SHARE.
A6: AR.VALID.3 | B6: Employment-to-Population Ratio (Total) | C6: 0.958 | D6: 0.958 | E6: BLS-derived | F6: High | G6: Exact after calibration.
A7: AR.VALID.4 | B7: Labor Force Participation Rate (Total) | C7: 0.59 | D7: 0.59 | E7: BLS LAUS | F7: High | G7: Exact match to record high.
A8: AR.VALID.5 | B8: Unemployment Rate (U3R) | C8: 0.042 | D8: 0.042 | E8: BLS LAUS | F8: High | G8: Exact match.
A9: AR.VALID.6 | B9: Underemployment Rate (U6R) | C9: 0.069 | D9: N/A | E9: Derived from U3R ratio | F9: Medium | G9: Consistent with BLS alt measures.
A10: AR.VALID.7 | B10: Average Hourly Wage (Total) | C10: 29.76 | D10: 29.76 | E10: BLS CES | F10: High | G10: Exact target.
A11: AR.VALID.8 | B11: Annual Income Average (Total) | C11: 54162 | D11: N/A | E11: Derived | F11: High | G11: Annualized consistent.
A12: AR.VALID.9 | B12: Total Federal PIT Revenue | C12: 9248649200 | D12: N/A | E12: Derived | F12: Medium | G12: Consistent with payroll/income.
A13: AR.VALID.10 | B13: Total Payroll Tax Revenue | C13: 11140613983 | D13: N/A | E13: Derived | F13: Medium | G13: Consistent.
A14: AR.VALID.11 | B14: Total EITC Refunds | C14: 150000000 | D14: ~150M | E14: IRS proxy | F14: Medium | G14: Prorated.
A15: AR.VALID.12 | B15: Total ACTC Refunds | C15: 120000000 | D15: ~120M | E15: IRS family | F15: Medium | G15: Consistent.
A16: AR.VALID.13 | B16: Total AOTC Refunds | C16: 80000000 | D16: ~80M | E16: IRS education | F16: Medium | G16: Aligned.
A17: AR.VALID.14 | B17: Net Fiscal Impact (labor-related, inferred) | C17: 2000000000 | D17: +1.8–2.2B | E17: ITEP/MPI | F17: Medium | G17: Positive net; improve with AR-specific study.
A18: AR.VALID.15 | B18: NPV per Capita 2035 (baseline forecast) | C18: 30000 | D18: ~28000–32000 | E18: BEA projection | F18: Low | G18: Speculative; growth assumptions.
A19: AR.VALID.16 | B19: Unauthorized Income Convergence Factor (moderate) | C19: 0.8 | D19: 0.75–0.85 | E19: MPI range | F19: Medium | G19: Mid-range scenario.
A20: AR.VALID.17 | B20: Manufacturing Employment | C20: 165600 | D20: 165.6 | E20: BLS CES | F20: High | G20: Exact match.
A21: AR.VALID.18 | B21: Leisure & Hospitality Employment | C21: 133000 | D21: 133 | E21: BLS CES | F21: High | G21: Exact match.
A22: AR.VALID.19 | B22: Construction Employment | C22: 65000 | D22: 65 | E22: BLS CES | F22: High | G22: Exact match.

Sheet LFP
A1: LSD.RID.0.AR.LFP | B1: Arkansas Labor Force Population (LFP) | C1: December 2025 | D1: Authorized, Unauthorized, American Labor Force Population By Industrial Labor Role
A2: LIRVID | B2: Industry: Role | C2: =CALC!D3 -> Labor Force Population | D2: =CALC!E3 -> Authorized Labor Force Population | E2: =CALC!F3 -> Unauthorized Labor Force Population | F2: =CALC!G3 -> American Labor Force Population
A3: =_xlfn.CONCAT($A$1, ".", CALC!A4) -> LSD.RID.0.AR.LFP.0 | B3: =_xlfn.CONCAT(CALC!B4, ":", CALC!C4) -> All Industries:All Roles | C3: =CALC!D4 -> 1444246 | D3: =CALC!E4 -> 57770 | E3: =CALC!F4 -> 50000 | F3: =CALC!G4 -> 1335928
A4: =_xlfn.CONCAT($A$1, ".", CALC!A5) -> LSD.RID.0.AR.LFP.1 | B4: =_xlfn.CONCAT(CALC!B5, ": ", CALC!C5) -> Agriculture: Worker | C4: =CALC!D5 -> 28319 | D4: =CALC!E5 -> 1133 | E4: =CALC!F5 -> 1962 | F4: =CALC!G5 -> 23788
A5: =_xlfn.CONCAT($A$1, ".", CALC!A6) -> LSD.RID.0.AR.LFP.2 | B5: =_xlfn.CONCAT(CALC!B6, ": ", CALC!C6) -> Agriculture: Support | C5: =CALC!D6 -> 7080 | D5: =CALC!E6 -> 283 | E5: =CALC!F6 -> 491 | F5: =CALC!G6 -> 5947
A6: =_xlfn.CONCAT($A$1, ".", CALC!A7) -> LSD.RID.0.AR.LFP.3 | B6: =_xlfn.CONCAT(CALC!B7, ": ", CALC!C7) -> Construction: Worker | C6: =CALC!D7 -> 55363 | D6: =CALC!E7 -> 2215 | E6: =CALC!F7 -> 5754 | F6: =CALC!G7 -> 43183
A7: =_xlfn.CONCAT($A$1, ".", CALC!A8) -> LSD.RID.0.AR.LFP.4 | B7: =_xlfn.CONCAT(CALC!B8, ": ", CALC!C8) -> Construction: Support | C7: =CALC!D8 -> 13841 | D7: =CALC!E8 -> 554 | E7: =CALC!F8 -> 1439 | F7: =CALC!G8 -> 10796
A8: =_xlfn.CONCAT($A$1, ".", CALC!A9) -> LSD.RID.0.AR.LFP.5 | B8: =_xlfn.CONCAT(CALC!B9, ": ", CALC!C9) -> Hospitality: Worker | C8: =CALC!D9 -> 119700 | D8: =CALC!E9 -> 4788 | E8: =CALC!F9 -> 9576 | F8: =CALC!G9 -> 99336
A9: =_xlfn.CONCAT($A$1, ".", CALC!A10) -> LSD.RID.0.AR.LFP.6 | B9: =_xlfn.CONCAT(CALC!B10, ": ", CALC!C10) -> Hospitality: Support | C9: =CALC!D10 -> 29925 | D9: =CALC!E10 -> 1197 | E9: =CALC!F10 -> 2394 | F9: =CALC!G10 -> 24834
A10: =_xlfn.CONCAT($A$1, ".", CALC!A11) -> LSD.RID.0.AR.LFP.7 | B10: =_xlfn.CONCAT(CALC!B11, ": ", CALC!C11) -> Cleaning & Maintenance: Worker | C10: =CALC!D11 -> 42500 | D10: =CALC!E11 -> 1700 | E10: =CALC!F11 -> 4250 | F10: =CALC!G11 -> 36550
A11: =_xlfn.CONCAT($A$1, ".", CALC!A12) -> LSD.RID.0.AR.LFP.8 | B11: =_xlfn.CONCAT(CALC!B12, ": ", CALC!C12) -> Cleaning & Maintenance: Support | C11: =CALC!D12 -> 10625 | D11: =CALC!E12 -> 425 | E11: =CALC!F12 -> 1063 | F11: =CALC!G12 -> 9138
A12: =_xlfn.CONCAT($A$1, ".", CALC!A13) -> LSD.RID.0.AR.LFP.9 | B12: =_xlfn.CONCAT(CALC!B13, ": ", CALC!C13) -> Manufacturing: Worker | C12: =CALC!D13 -> 149040 | D12: =CALC!E13 -> 5962 | E12: =CALC!F13 -> 11924 | F12: =CALC!G13 -> 131154
A13: =_xlfn.CONCAT($A$1, ".", CALC!A14) -> LSD.RID.0.AR.LFP.10 | B13: =_xlfn.CONCAT(CALC!B14, ": ", CALC!C14) -> Manufacturing: Support | C13: =CALC!D14 -> 37921 | D13: =CALC!E14 -> 1517 | E13: =CALC!F14 -> 5309 | F13: =CALC!G14 -> 31095
A14: =_xlfn.CONCAT($A$1, ".", CALC!A15) -> LSD.RID.0.AR.LFP.11 | B14: =_xlfn.CONCAT(CALC!B15, ": ", CALC!C15) -> Transportation & Warehousing: Worker | C14: =CALC!D15 -> 109556 | D14: =CALC!E15 -> 4382 | E14: =CALC!F15 -> 10956 | F14: =CALC!G15 -> 94218
A15: =_xlfn.CONCAT($A$1, ".", CALC!A16) -> LSD.RID.0.AR.LFP.12 | B15: =_xlfn.CONCAT(CALC!B16, ": ", CALC!C16) -> Transportation & Warehousing: Support | C15: =CALC!D16 -> 36519 | D15: =CALC!E16 -> 1461 | E15: =CALC!F16 -> 3652 | F15: =CALC!G16 -> 31406
... A55: =_xlfn.CONCAT($A$1, ".", CALC!A56) -> LSD.RID.0.AR.LFP.52 | B55: =_xlfn.CONCAT(CALC!B56, ": ", CALC!C56) -> Public Administration: Worker | C55: =CALC!D56 -> 85000 | D55: =CALC!E56 -> 3400 | E55: =CALC!F56 -> 6800 | F55: =CALC!G56 -> 74800

Sheet ETPR
A1: LSD.RID.0.AR.ETPR | B1: Arkansas Employment-to-Population Ratio (ETPR) | C1: December 2025 | D1: Authorized, Unauthorized, American Laborer Employment-to-Population Ratio By Industrial Labor Role
A2: LIRVID | B2: Industry: Role | C2: =CALC!H3 -> Employment-to-Population Ratio | D2: =CALC!I3 -> Authorized Immigrant Employment-to-Population Ratio | E2: =CALC!J3 -> Unauthorized Immigrant Employment-to-Population Ratio | F2: =CALC!K3 -> American Employment-to-Population Ratio
A3: =_xlfn.CONCAT($A$1, ".", CALC!A4) -> LSD.RID.0.AR.ETPR.0 | B3: =_xlfn.CONCAT(CALC!B4, ":", CALC!C4) -> All Industries:All Roles | C3: =CALC!H4 -> 0.958 | D3: =CALC!I4 -> 1 | E3: =CALC!J4 -> 0.9 | F3: =CALC!K4 -> 0.958
A4: =_xlfn.CONCAT($A$1, ".", CALC!A5) -> LSD.RID.0.AR.ETPR.1 | B4: =_xlfn.CONCAT(CALC!B5, ": ", CALC!C5) -> Agriculture: Worker | C4: =CALC!H5 -> 0.958 | D4: =CALC!I5 -> 0.98 | E4: =CALC!J5 -> 0.85 | F4: =CALC!K5 -> 0.958
A5: =_xlfn.CONCAT($A$1, ".", CALC!A6) -> LSD.RID.0.AR.ETPR.2 | B5: =_xlfn.CONCAT(CALC!B6, ": ", CALC!C6) -> Agriculture: Support | C5: =CALC!H6 -> 0.958 | D5: =CALC!I6 -> 0.98 | E5: =CALC!J6 -> 0.85 | F5: =CALC!K6 -> 0.958
A6: =_xlfn.CONCAT($A$1, ".", CALC!A7) -> LSD.RID.0.AR.ETPR.3 | B6: =_xlfn.CONCAT(CALC!B7, ": ", CALC!C7) -> Construction: Worker | C6: =CALC!H7 -> 0.958 | D6: =CALC!I7 -> 0.98 | E6: =CALC!J7 -> 0.88 | F6: =CALC!K7 -> 0.958
A7: =_xlfn.CONCAT($A$1, ".", CALC!A8) -> LSD.RID.0.AR.ETPR.4 | B7: =_xlfn.CONCAT(CALC!B8, ": ", CALC!C8) -> Construction: Support | C7: =CALC!H8 -> 0.958 | D7: =CALC!I8 -> 0.98 | E7: =CALC!J8 -> 0.88 | F7: =CALC!K8 -> 0.958
A8: =_xlfn.CONCAT($A$1, ".", CALC!A9) -> LSD.RID.0.AR.ETPR.5 | B8: =_xlfn.CONCAT(CALC!B9, ": ", CALC!C9) -> Hospitality: Worker | C8: =CALC!H9 -> 0.958 | D8: =CALC!I9 -> 0.98 | E8: =CALC!J9 -> 0.9 | F8: =CALC!K9 -> 0.958
A9: =_xlfn.CONCAT($A$1, ".", CALC!A10) -> LSD.RID.0.AR.ETPR.6 | B9: =_xlfn.CONCAT(CALC!B10, ": ", CALC!C10) -> Hospitality: Support | C9: =CALC!H10 -> 0.958 | D9: =CALC!I10 -> 0.98 | E9: =CALC!J10 -> 0.9 | F9: =CALC!K10 -> 0.958
A10: =_xlfn.CONCAT($A$1, ".", CALC!A11) -> LSD.RID.0.AR.ETPR.7 | B10: =_xlfn.CONCAT(CALC!B11, ": ", CALC!C11) -> Cleaning & Maintenance: Worker | C10: =CALC!H11 -> 0.958 | D10: =CALC!I11 -> 0.98 | E10: =CALC!J11 -> 0.9 | F10: =CALC!K11 -> 0.958
A11: =_xlfn.CONCAT($A$1, ".", CALC!A12) -> LSD.RID.0.AR.ETPR.8 | B11: =_xlfn.CONCAT(CALC!B12, ": ", CALC!C12) -> Cleaning & Maintenance: Support | C11: =CALC!H12 -> 0.958 | D11: =CALC!I12 -> 0.98 | E11: =CALC!J12 -> 0.9 | F11: =CALC!K12 -> 0.958
