Workbook

Sheet INDEX
A1: LSD.RID.0.AL | B1: Alabama Labor Statistics | C1: December 2025
A2: TID | B2: Title | C2: Month
A3: =INVOKE!A$1 -> LSD.REF.AL.INVOKE | B3: =INVOKE!B$1 -> Alabama Labor Statistic Logic Formulae | C3: =INVOKE!C$1 -> December 2025
A4: =FORM!A$1 -> LSD.REF.AL.FORM | B4: =FORM!B$1 -> Alabama Labor Statistic Logic Formulae | C4: =FORM!C$1 -> December 2025
A5: =PARAM!A$1 -> LSD.REF.AL.PARAM | B5: =PARAM!B$1 -> Alabama Labor Statistic Logic Parameters | C5: =PARAM!C$1 -> December 2025
A6: =CALC!A1 -> LSD.RID.0.AL.CALC | B6: =CALC!B1 -> Alabama Labor Statistic Calculations | C6: =CALC!C1 -> December 2025
A7: =VALID!A1 -> LSD.RID.0.AL.VALID | B7: =VALID!B1 -> Alabama Labor Statistic Calculation Validation | C7: =VALID!C1 -> December 2025
A8: =LFP!A1 -> LSD.RID.0.AL.LFP | B8: =LFP!B1 -> Alabama Labor Force Population (LFP) | C8: =LFP!C1 -> December 2025
A9: =ETPR!A1 -> LSD.RID.0.AL.ETPR | B9: =ETPR!B1 -> Alabama Employment-to-Population Ratio (ETPR) | C9: =ETPR!C1 -> December 2025
A10: =LFPR!A1 -> LSD.RID.0.AL.LFPR | B10: =LFPR!B1 -> Alabama Labor Force Participation Rate (LFPR) | C10: =LFPR!C1 -> December 2025
A11: =U3R!A1 -> LSD.RID.0.AL.U3R | B11: =U3R!B1 -> Alabama Unemployment Rate (U3R) | C11: =U3R!C1 -> December 2025
A12: =U6R!A1 -> LSD.RID.0.AL.U6R | B12: =U6R!B1 -> Alabama Underemployment Rate (U6R) | C12: =U6R!C1 -> December 2025
A13: =WAVG!A1 -> LSD.RID.0.AL.WAVG | B13: =WAVG!B1 -> Alabama Wage Average (WAVG) | C13: =WAVG!C1 -> December 2025
A14: =AIAVG!A1 -> LSD.RID.0.AL.AIAVG | B14: =AIAVG!B1 -> Alabama Annual Income Average (AIAVG) | C14: =AIAVG!C1 -> December 2025
A15: =FPITREV!A1 -> LSD.RID.0.AL.FPITREV | B15: =FPITREV!B1 -> Alabama Federal Personal Income Tax Revenue (FPITREV) | C15: =FPITREV!C1 -> December 2025
A16: =FPPTREV!A1 -> LSD.RID.0.AL.FPPTR | B16: =FPPTREV!B1 -> Alabama Federal Personal Payrol Tax Revenue | C16: =FPPTREV!C1 -> December 2025
A17: =EITCREF!A1 -> LSD.RID.0.AL.EITCREF | B17: =EITCREF!B1 -> Alabama Earned Income Tax Credit Refund | C17: =EITCREF!C1 -> December 2025
A18: =ACTCREF!A1 -> LSD.RID.0.AL.ACTCREF | B18: =ACTCREF!B1 -> Alabama Additional Child Tax Credit Refund | C18: =ACTCREF!C1 -> December 2025
A19: =AOTCREF!A1 -> LSD.RID.0.AL.AOTCREF | B19: =AOTCREF!B1 -> Alabama American Opportunity Tax Credit Refund | C19: =AOTCREF!C1 -> December 2025
A21: LSD.RID.0.AL.GLOSS | B21: Alabama Labor Statistic Calculations | C21: Calculated formulae use parameters.
A22: GLOID | B22: Glossary Name | C22: Definition
A23: 0 | B23: RID | C23: Region ID
A24: 1 | B24: DES | C24: Department of Economic Security
A25: 2 | B25: LSD | C25: Labor Security Division
A26: 3 | B26: SLIID | C26: State Labor Industry ID
A27: 4 | B27: SLIVID | C27: State Labor Industry Visualization ID
A28: 5 | B28: INVID | C28: Invocation ID
A29: 6 | B29: RID | C29: Region ID
A30: 7 | B30: LFP | C30: Labor Force Population
A31: 8 | B31: ETPR | C31: Employment-to-Population Ratio
A32: 9 | B32: LFPR | C32: Labor Force Population Rate
... A57: 34 | B57: VALID | C57: Validations

Sheet INVOKE
A1: LSD.REF.AL.INVOKE | B1: Alabama Labor Statistic Logic Formulae | C1: December 2025
A2: INVID | B2: Invocation Name | C2: Invocation Script | D2: References | E2: Reference Account | F2: Branch A
A3: 16 | B3: Alabama Labor Statistic Reformulation, Reparameterization, Recalculation Through Restructuring | C3: Consider the attached spreadsheet containing U.S. Labor Statistic Formulae, Parameters, and Calculations for the state of Alabama. Notice the drafted INDEX table containing various references for the remaining tabs. The purpose of this session is to restructure tabs: - FORMulae and PARAMeters for **interdependent** labor statistic calculations will remain in FORM. - FORMulae and PARAMeters for **independent** labor statistic metrics and measures should be isolated and will be copy-pasted into correspective metric tabs. - FORMulae and PARAMeters restructuring should include refinement such as additions, editions. - FORMulae and PARAMeters should have correlated identifiers in the format of the metric's acronym, followed by a single "." character (period), follwed by an index number (starting with 0) - such as LFP.0, LFP.1, etc. - FORMulae and PARAMeters should follow same column structure. All output should be performed metric-by-metric - with the exception of the shared FORMulae and PARAMeters, which should be created first. While revising or restructuring FORMulae and PARAMeters if there are additional/editional **shared** FORMulae and PARAMeters, then the tabular data should be generated so that it may be copy-pasted during the process. Prompt to continue. | D3: https://grok.com/share/c2hhcmQtMi1jb3B5_b42b6690-ea62-4ca7-8092-8da4e8765ff9 | E3: thomas.welborn@protonmail.com
A4: 15 | B4: Alabama Labor Statistics Formulae, Parameter, Calculation Refinement Session | C4: Consider the attached spreadsheet containing U.S. Labor Statistics for Alabama. This is a draft document in partial state of completion. Notice the FORM tab containing formulae and PARAM tab containing parameters that combined calculate CALC table: Alabama Labor Statistics. VALID tab describes latest CALCulation validation. Further tabs are references to CALC table for measure-specific data visualization and analysis purposes. The current state of drafting is refinement of calculations using exhaustive formulae and parameters tables. Notice that previous states of drafting are references on the INDEX tab. There are over 30 Metrics and more submetrics in the CALC. This session will continue prior Grok sessions. When generating content follow these rules: output must be in tsv format that is copy-pasteable as an formatted, embedded table; long output must be truncated by grouped sequences that optimize Grok's performance; FORM, PARAM, and CALC table creation must use the same column/row headers as in LSD.RID.0.AL spreadsheet. When performing calculations or considering spreadsheet content, ignore all tabs after CALC - these tabs are CALC references. Prompt me to continue with next segue. | D4: https://grok.com/share/c2hhcmQtMi1jb3B5_3d42fed3-3e96-4239-9e2f-0193ac9134fa | E4: thomas.tom.welborn@gmail.com
A5: 14 | B5: Alabama Labor Statistics Formulae, Parameter, Calculation Refinement Session | C5: Consider the attached spreadsheet containing U.S. Labor Statistics for Alabama. This is a draft document in partial state of completion. Notice the FORM tab containing formulae and PARAM tab containing parameters that combined calculate CALC table: Alabama Labor Statistics. VALID tab describes latest CALCulation validation. Further tabs are references to CALC table for measure-specific data visualization and analysis purposes. The current state of drafting is refinement of calculations using exhaustive formulae and parameters tables. Notice that previous states of drafting are references on the INDEX tab. There are over 30 Metrics and more submetrics in the CALC. This session will continue prior Grok sessions. When generating content follow these rules: output must be in tsv format that is copy-pasteable as an formatted, embedded table; long output must be truncated by grouped sequences that optimize Grok's performance; FORM, PARAM, and CALC table creation must use the same column/row headers as in LSD.RID.0.AL spreadsheet. When performing calculations or considering spreadsheet content, ignore all tabs after CALC - these tabs are CALC references. Prompt me to continue with next segue. | D5: https://grok.com/share/c2hhcmQtMi1jb3B5_05a1dd6b-e942-4559-ba6a-f3b1f2ab03fe | E5: thomas.welborn@protonmail.com
A6: 13 | B6: Alabama Labor Statistics Formulae, Parameter, Calculation Refinement Session | C6: Consider the attached spreadsheet containing U.S. Labor Statistics for Alabama. This is a draft document in partial state of completion. Notice the FORM tab containing formulae and PARAM tab containing parameters that combined calculate CALC table: Alabama Labor Statistics. VALID tab describes latest CALCulation validation. Further tabs are references to CALC table for measure-specific data visualization and analysis purposes. The current state of drafting is refinement of calculations using exhaustive formulae and parameters tables. Notice that previous states of drafting are references on the INDEX tab. There are over 30 Metrics and more submetrics in the CALC. This session will continue prior Grok sessions. When generating content follow these rules: output must be in tsv format that is copy-pasteable as an formatted, embedded table; long output must be truncated by grouped sequences that optimize Grok's performance; FORM, PARAM, and CALC table creation must use the same column/row headers as in LSD.RID.0.AL spreadsheet. When performing calculations or considering spreadsheet content, ignore all tabs after CALC - these tabs are CALC references. Prompt me to continue with next segue. | D6: https://grok.com/share/c2hhcmQtMi1jb3B5_38c5a765-74c2-4109-9029-b59b07945946 | E6: thomas.welborn@protonmail.com
A7: 12 | B7: Alabama Labor Statistics Formulae, Parameter, Calculation Refinement Session | C7: Consider the attached spreadsheet containing U.S. Labor Statistics for Alabama. This is a draft document in partial state of completion. Notice the FORM tab containing formulae and PARAM tab containing parameters that combined calculate CALC table: Alabama Labor Statistics. Further tabs are references to CALC table for data visualization and analysis purposes. The current state of drafting is refinement of calculations using exhaustive formulae and parameters tables. Notice that previous states of drafting are references on the (incomplete) INDEX tab. There are over 30 Metrics and more submetrics in the CALC. This session will continue prior Grok sessions. When generating content follow these rules: output must be in `tsv` format that is copy-pasteable as an formatted, embedded table; long output must be truncated by grouped sequences that optimize Grok's performance. When performing calculations or considering spreadsheet content, ignore all tabs after `CALC` - these tabs are CALC references. Prompt me to continue. | D7: https://grok.com/share/c2hhcmQtMg_4d848e26-26c7-4725-849f-6a1a29e77d95 | E7: thomas.tom.welborn@gmail.com
A8: 11 | B8: Alabama Labor Statistics Formulae, Parameter, Calculation Refinement Session | C8: Consider the attached spreadsheet containing U.S. Labor Statistics for Alabama. This is a draft document in partial state of completion. Notice the FORM tab containing formulae and PARAM tab containing parameters that combined calculate CALC table: Alabama Labor Statistics. Further tabs are references to CALC table for data visualization and analysis purposes. The current state of drafting is refinement of calculations using exhaustive formulae and parameters tables. Notice that previous states of drafting are references on the (incomplete) INDEX tab. There are over 30 Metrics and more submetrics in the CALC. This session will continue prior Grok sessions. When generating content follow these rules: output must be in `tsv` format that is copy-pasteable as an formatted, embedded table; long output must be truncated by grouped sequences that optimize Grok's performance. When performing calculations or considering spreadsheet content, ignore all tabs after `CALC` - these tabs are CALC references. Prompt me to continue. | D8: https://grok.com/share/bGVnYWN5LWNvcHk_5cd45c1a-a286-44d3-94ef-a0cf30f63a73 | E8: thomas.patrick.welborn@outlook.com | F8: The calculations for some metric measurements should be refined through formuale and parameters to become more specific and differentiated between each other (realistic organic representations of estimates). Consider the following example calculation refinement scenarios, then describe how to further refine these for accuracy: **Refinement A** - Notice the U3R tab, which (CALC derivative): the "Unemployment Rate" and "Authorized Unemployment Rate" Measurements mirror each other, even though the "Unemployment Rate" refers to overall unemployment rate comprised of "Unauthorized Unemployment Rate", "Authorized Unemployment Rate", and "American Unemployment Rate"; measurements should only mirror each other when accurate or accurately estimated values are recorded; Recreate formulae and parameters that calculate any measurements that resemble this. **Refinement B**
A9: 10 | B9: Alabama Labor Statistics Calculation Session | C9: Consider the attached spreadsheet containing U.S. Labor Statistic Formulae, Parameters, and Calculations for the state of Alabama. Notice the drafted INDEX table containing various references for the remaining tabs. The `FORM` tab contains formulae describing Alabama Labor Statistic Calculations; the `PARAM` tab contains parameters used by `FORM`ulae to calculate Alabama Labor Statistics; the `CALC` tab contains labor statistic calculations. This session is to perform calulcations from existing formulae and parameters from prior sessions, then to validate the table for accuracy. This session may also include refinements to `FORM` and `PARAM` tabs for more accurate estimations or calculations. Because of large volume of calculations all labor statistic calculations, formulae, and parameter output must be done in sections of rows, prompting me to continue between row generation. All output should be in TSV format. It should not be truncated unless specified. This is a continuation of another similar session that was interrupted due to session token limits. During the last session machine prompted to refine formulae after already refining PARAM. This session should start by continuing the last session (INVID#7) from it's reference. Prompt me to continue. | D9: https://grok.com/share/c2hhcmQtMg_31b2cba9-0fd7-4cb0-a163-e11fe3df530b | E9: thomas.tom.welborn@gmail.com
A10: 9 | B10: Alabama Labor Statistic Calculations | C10: Consider the attached spreadsheet containing U.S. Labor Statistic Formulae, Parameters, and Calculations for the state of Alabama. Notice the drafted INDEX table containing various references for the remaining tabs. The FORM tab contains formulae describing Alabama Labor Statistic Calculations; the PARAM tab contains parameters used by FORMulae to calculate Alabama Labor Statistics; the CALC tab contains labor statistic calculations. This session is to perform calulcations from existing formulae and parameters from prior sessions, then to validate the table for accuracy. This session may also include refinements to FORM and PARAM tabs for more accurate estimations or calculations. Because of large volume of calculations all labor statistic calculations, formulae, and parameter output must be done in sections of rows, prompting me to continue between row generation. All output should be in TSV format. It should not be truncated unless specified. This is a continuation of another similar session that was interrupted due to session token limits. During the last session machine prompted to refine formulae after already refining PARAM. This session should start by continuing the last session (INVID#7) from it's reference. Prompt me to continue. | D10: https://grok.com/share/bGVnYWN5LWNvcHk_316f106c-153c-4f0b-829f-7a8355ecb81b | E10: thomas.patrick.welborn@outlook.com
A11: 8 | B11: Alabama Labor Statistic Calculations | C11: Consider the attached spreadsheet containing U.S. Labor Statistic Formulae, Parameters, and Calculations for the state of Alabama. Notice the drafted INDEX table containing various references for the remaining tabs. The `FORM` tab contains formulae describing Alabama Labor Statistic Calculations; the `PARAM` tab contains parameters used by `FORM`ulae to calculate Alabama Labor Statistics; the `CALC` tab contains labor statistic calculations. This session is to perform calulcations from existing formulae and parameters from prior sessions, then to validate the table for accuracy. This session may also include refinements to `FORM` and `PARAM` tabs for more accurate estimations or calculations. Because of large volume of calculations all labor statistic calculations, formulae, and parameter output must be done in sections of rows, prompting me to continue between row generation. All output should be in TSV format. It should not be truncated unless specified. Prompt me to continue. | E11: thomas.tom.welborn@gmail.com
A12: 7 | B12: Alabama Labor Statistic Calculations | C12: Consider the attached spreadsheet containing U.S. Labor Statistic Formulae, Parameters, and Calculations for the state of Alabama. Notice the drafted INDEX table containing various references for the remaining tabs. The `FORM` tab contains formulae describing Alabama Labor Statistic Calculations; the `PARAM` tab contains parameters used by `FORM`ulae to calculate Alabama Labor Statistics; the `CALC` tab contains labor statistic calculations. This session is to perform calulcations from existing formulae and parameters from prior sessions, then to validate the table for accuracy. This session may also include refinements to `FORM` and `PARAM` tabs for more accurate estimations or calculations. Because of large volume of calculations all labor statistic calculations, formulae, and parameter output must be done in sections of rows, prompting me to continue between row generation. All output should be in TSV format. It should not be truncated unless specified. Prompt me to continue. | D12: https://grok.com/share/bGVnYWN5LWNvcHk_316f106c-153c-4f0b-829f-7a8355ecb81b | E12: thomas.patrick.welborn@outlook.com
A13: 6 | B13: Alabama Labor Statistics Formulae | C13: Consider the attached spreadsheet containing U.S. Labor Statistics for Alabama. This is a draft document in partial state of completion. Notice the FORM tab containing formulae and PARAM tab containing parameters that combined calculate CALC table: Alabama Labor Statistics. Further tabs are references to CALC table for data visualization and analysis purposes. The current state of drafting is refinement of calculations using exhaustive formulae and parameters tables. Notice that previous states of drafting are references on the (incomplete) INDEX tab. There are over 30 Metrics and more submetrics in the CALC. This session will continue another session from another Grok account. Currently FORM rows are being added to consume the comprehensive PARAM (parameters) – a continuation of INDEX tab INVID#5 session. Continue generating formulae to support all metric calculations using parameters. Create 20 rowed entries before prompting me to continue to next 20. Ask me questions to clarify either instructions herein or inability to reference materials or accomplish task as intended. | D13: https://grok.com/share/c2hhcmQtMi1jb3B5_9a9978e6-49f9-41d5-9b57-896863210d16 | E13: thomas.patrick.welborn@outlook.com
A14: 5 | B14: Expand Labor Statistic Metric Formulae And Parameters | C14: Consider the attached spreadsheet containing U.S. Labor Statistics for Alabama. This is a draft document in partial state of completion. Notice the FORM tab containing formulae and PARAM tab containing parameters that combined calculate CALC table: Alabama Labor Statistics. Further tabs are references to CALC table for data visualization and analysis purposes. The current state of drafting is refinement of calculations using exhaustive formulae and parameters tables. Notice that previous states of drafting are references on the (incomplete) INDEX tab. There are over 30 Metrics and more submetrics in the CALC. This session will continue another session from another Grok account. Currently PARAM rows are being added to support all of the formulae – a continuation of INDEX tab INVID#4 session. Continue generating parameters to support all formulae calculations for remaining metrics. Parametered values should continue to be categorized with row headers. Create 50 rowed entries before prompting me to continue to next 50. Ask me questions to clarify either instructions herein or inability to reference materials or accomplish task as intended. | D14: https://grok.com/share/c2hhcmQtMg_16f7a2a6-b28c-45ad-bac9-7243cbefac56 | E14: thomas.tom.welborn@gmail.com
A15: 4 | B15: Expand Labor Metrics and Industry Roles | C15: N/A | D15: https://grok.com/share/bGVnYWN5LWNvcHk_9ffcfa10-bc66-492d-b499-a56dc57d6238 | E15: thomas.patrick.welborn@outlook.com
A16: 3 | B16: Alabama, Arkansas, Florida Labor Statistics Formulae, Parameters, Calculations | C16: N/A | D16: https://grok.com/share/c2hhcmQtMi1jb3B5_e3140b59-169a-487d-9539-b52e3cb64dad | E16: thomas.welborn@protonmail.com
A17: 2 | B17: Alabama, Arkansas Labor Statistics Calculations | C17: This session's purpose is to calculate labor statistics for individual states in a region. Each state's labor stastic calculations will be performed independently and using predefined formulae. Output should be in copy-pasteable `TSV` format. `LSD.REF` spreadsheet details formulae and parameters required for calculations of regionalized state labor statistics. `RID.*` spreadsheets are comprised of individual state tabs with primary tables of performed calculations, then altertables in each state's tab remain references to primary table. All tables in the spreadsheet should be calculated with latest formulae and parameters from spreadsheet. When requested during this session calculate a specified state's labor statistics. Afterward validate the calculated table against alter public sources. Prompt me to continue. | D17: https://grok.com/share/c2hhcmQtMg_d3d49fd1-59fe-445a-b9c5-74ad95e6913d | E17: thomas.tom.welborn@gmail.com
A18: 1 | B18: Arkansas Labor Statistics Calculations | C18: This session's purpose is to calculate labor statistics for each state in a region. Each state's labor stastic calculations will be performed independently and using predefined formulae. Output should be in copy-pasteable `TSV` format. `LSD.REFERENCE` spreadsheet details `FORMULAE.REGION` and `FORMULAE.STATE` calculations for regionalized states, as well as other parameterized tabs referenced by formulae. Formulae tabs are pseudocode and require calculations performed as machine instructions. `RID.0` is comprised of individual state tabs with primary tables of performed calculations, then altertables in each state's tab remain references to primary table. All table in the spreadsheet should be calculated with latest formulae and parameters from spreadsheet. When requested during this session calculate a specified state's labor statistics. Afterward validate the calculated table against alter public sources. Prompt me to continue. | D18: https://grok.com/share/c2hhcmQtMg_05f8d4b3-2d59-4349-93d9-6c5bafa3bacd | E18: thomas.patrick.welborn@outlook.com
A19: 0 | B19: Alabama Labor Statistics Calculations | C19: This session's purpose is to calculate labor statistics for each state in a region. Each state's labor stastic calculations will be performed independently and using predefined formulae. Output should be in copy-pasteable `TSV` format. `LSD.REFERENCE` spreadsheet details `FORMULAE.REGION` and `FORMULAE.STATE` calculations for regionalized states, as well as other parameterized tabs referenced by formulae. Formulae tabs are pseudocode and require calculations performed as machine instructions. `RID.0` is comprised of individual state tabs with primary tables of performed calculations, then altertables in each state's tab remain references to primary table. All table in the spreadsheet should be calculated with latest formulae and parameters from spreadsheet. When requested during this session calculate a specified state's labor statistics. Afterward validate the calculated table against alter public sources. Prompt me to continue. | D19: https://grok.com/share/c2hhcmQtMg_9fc2e9b2-bc97-4724-b16d-fc3d1e8312f2 | E19: thomas.tom.welborn@gmail.com

Sheet FORM
A1: LSD.REF.AL.FORM | B1: Alabama Labor Statistic Logic Formulae | C1: December 2025
A2: S0 - Shared/Base | B2: S0 | C2: Shared - Base Lookups and Prorations | D2: (empty) | E2: (empty) | F2: (empty)
A3: S0 - Shared/Base | B3: S0.0 | C3: Industry Employment Total | D3: T_i = PARAMETERS!TOTAL_NONFARM_AL * PARAMETERS!INDUSTRY_SHARE[i] + PARAMETERS!ADJUSTMENT_FACTOR_IND[i] | E3: BLS CES base + adjustment for ag/self-employed | F3: Ensure sum(T_i) ≈ PARAMETERS!BLS_EP_TOTAL_TARGET; use VLOOKUP; edited to include new PARAM for mining/logging share
A4: S0 - Shared/Base | B4: S0.1 | C4: Role Proration (Worker/Support) | D4: ROLE_WORKER_i = T_i * PARAMETERS!ROLE_PRORATE_WORKER_IND[i]; ROLE_SUPPORT_i = T_i - ROLE_WORKER_i | E4: Split employment into Worker/Support | F4: Defaults 75/25 if missing; edited to use industry-specific prorates from ACS for construction and finance to address low validation
A5: S0 - Shared/Base | B5: S0.2 | C5: Population Share Proration (Auth/Unauth/American) | D5: AUTH_SHARE_i = PARAMETERS!AUTH_IMMIGRANT_SHARE_IND[i]; UNAUTH_SHARE_i = PARAMETERS!UNAUTH_IMMIGRANT_SHARE_IND[i]; AMER_SHARE_i = 1 - AUTH_SHARE_i - UNAUTH_SHARE_i | E5: Prorate by immigrant shares from MPI/ACS | F5: Apply global cap: if SUM(UNAUTH_SHARE_i * T_i) > P078 * TOTAL_NONFARM_AL then prorate UNAUTH_SHARE_i down proportionally (FID 300.21); edited cap to use updated P078 for better MPI alignment
A6: S0 - Shared/Base | B6: S0.3 | C6: Data Fusion for Multi-Source Blending | D6: value_i = (PARAMETERS!BLS_VALUE_IND[i] * PARAMETERS!ACCURACY_BLS + PARAMETERS!ACS_VALUE_IND[i] * PARAMETERS!ACCURACY_ACS + PARAMETERS!MPI_VALUE_IND[i] * PARAMETERS!ACCURACY_MPI) / (PARAMETERS!ACCURACY_BLS + PARAMETERS!ACCURACY_ACS + PARAMETERS!ACCURACY_MPI) | E6: Weighted avg of sources by accuracy ratings (e.g., BLS high=0.95, ACS medium=0.6, MPI=0.5) | F6: Apply to rates/wages; recency_factor optional (e.g., *0.95 if >1yr old); 90% robustness; edited to increase BLS weight to 0.95 for employment totals to match CES data
A7: S0 - Shared/Base | B7: S0.5 | C7: Employed Population by Group | D7: EP_total_i = S0.5_EP_total_i | E7: From shared | F7: 95% accuracy
A8: LFP Group | B8: 100 | C8: Industry/Role-Specific Core Labor Metrics | D8: LFP_total_i = S1_T_i / S6_ETPR_total_i | E8: Back-calculate from adjusted employment and industry ETPR | F8: Primary driver of all downstream population-based metrics; 95% accuracy target
A9: LFP Group | B9: 100.48 | C9: Employed Population (EP) – Total | D9: EP_total_i = S0.5_EP_total_i | E9: From shared | F9: 95% accuracy
A10: LFP Group | B10: 100.49 | C10: Employed Population (EP) – Authorized | D10: EP_auth_i = S0.5_EP_auth_i | E10: From shared | F10: (empty)
A11: LFP Group | B11: 100.5 | C11: Employed Population (EP) – Unauthorized | D11: EP_unauth_i = S0.5_EP_unauth_i | E11: From shared | F11: (empty)
A12: LFP Group | B12: 100.51 | C12: Employed Population (EP) – American | D12: EP_amer_i = S0.5_EP_amer_i | E12: From shared | F12: (empty)
A13: LFP Group | B13: 100.52 | C13: Average Weekly Hours Worked – Total | D13: AWHW_total_i = S4.0_AWHW_total_i | E13: From shared | F13: 95% accuracy
A14: LFP Group | B14: 100.53 | C14: Average Weekly Hours Worked – Authorized | D14: AWHW_auth_i = S4.0_AWHW_auth_i | E14: From shared | F14: (empty)
A15: LFP Group | B15: 100.54 | C15: Average Weekly Hours Worked – Unauthorized | D15: AWHW_unauth_i = S4.0_AWHW_unauth_i | E15: From shared | F15: (empty)
A16: LFP Group | B16: 100.55 | C16: Average Weekly Hours Worked – American | D16: AWHW_amer_i = S4.0_AWHW_amer_i | E16: From shared | F16: (empty)
A17: LFP Group | B17: 100.56 | C17: Full-Time Employment Rate – Total | D17: FTER_total_i = S4.1_FTER_total_i | E17: From shared | F17: 90% accuracy
A18: LFP Group | B18: 100.57 | C18: Full-Time Employment Rate – Authorized | D18: FTER_auth_i = S4.1_FTER_auth_i | E18: From shared | F18: (empty)
A19: LFP Group | B19: 100.58 | C19: Full-Time Employment Rate – Unauthorized | D19: FTER_unauth_i = S4.1_FTER_unauth_i | E19: From shared | F19: (empty)
... A24: LFP Group | B24: 100.63 | C24: Part-Time Employment Rate – American | D24: PTER_amer_i = S4.2_PTER_amer_i | E24: From shared | F24: (empty)
A25: ETPR Group | B25: S1 | C25: Shared - Rate Calculations | D25: ETPR_total_i = PARAMETERS!ETPR_IND[i]; ETPR_auth_i = ETPR_total_i * (1 + PARAMETERS!IMMIGRANT_ETPR_ADJ); ETPR_unauth_i = ETPR_total_i * (1 + PARAMETERS!UNAUTH_ETPR_ADJ); ETPR_amer_i = weighted residual | E25: Industry ETPR from BLS + immigrant adj | F25: Weighted avg must ≈ state ETPR ~56.1%
A26: WAVG Group | B26: S2 | C26: Shared - Wage and Income | D26: WAVG_total_i = PARAMETERS!WAVG_IND[i]; WAVG_auth_i = WAVG_total_i * PARAMETERS!IMMIGRANT_WAGE_FACTOR; WAVG_unauth_i = max(PARAMETERS!MIN_WAGE_AL, WAVG_total_i * PARAMETERS!UNAUTH_WAGE_FACTOR); WAVG_amer_i = weighted residual | E26: BLS OES/QCEW wages + immigrant factors | F26: Added floor to prevent unrealistically low unauth wages; edited for wage calibration
A27: AIAVG Group | B27: S2.1 | C27: Annual Income Average by Group | D27: AIAVG_amer_i = WAVG_amer_i * PARAMETERS!AWHW_IND[i] * 52 * PARAMETERS!OVERTIME_ADJ_IND[i]; AIAVG_auth_i = AIAVG_amer_i * PARAMETERS!IMMIGRANT_WAGE_GAP_FACTOR_IND[i]; AIAVG_unauth_i = AIAVG_amer_i * PARAMETERS!UNAUTH_WAGE_GAP_FACTOR_IND[i]; AIAVG_total_i = (AIAVG_auth_i * EP_auth_i + AIAVG_unauth_i * EP_unauth_i + AIAVG_amer_i * EP_amer_i) / EP_total_i | E27: Annualize with industry hours/overtime adj; gaps as in S2.0 | F27: 90% accuracy; add educ/experience adj via PARAMETERS!EDUC_ADJ_GROUP[i] (auth 0.9, unauth 0.7); edited to blend ACS/BEA per capita with inflation adjustment to 2026
A28: FPITREV Group | B28: S3 | C28: Shared - Tax and Credits | D28: FPITREV_total_i = AIAVG_total_i * EP_total_i * PARAMETERS!FED_PIT_RATE; ... (same structure) | E28: Effective PIT rate from IRS; unauth lower | F28: Apply fiscal calibration scale post-sum (new FID S3.5)
A29: FPITREV Group | B29: S3.0 | C29: Federal Personal Income Tax Revenue by Group | D29: FPITREV_amer_i = AIAVG_amer_i * EP_amer_i * PARAMETERS!FED_PIT_RATE_AMER; FPITREV_auth_i = AIAVG_auth_i * EP_auth_i * PARAMETERS!FED_PIT_RATE_AUTH; FPITREV_unauth_i = AIAVG_unauth_i * EP_unauth_i * PARAMETERS!FED_PIT_RATE_UNAUTH * PARAMETERS!FILING_RATE_UNAUTH; FPITREV_total_i = FPITREV_auth_i + FPITREV_unauth_i + FPITREV_amer_i | E29: Effective PIT rates by group (unauth lower 0.08 due to underreporting/ITIN, filing 0.6); total sum | F29: Blend IRS (0.6 wt), CBO (0.3), state (0.1); ±15% unauth uncertainty; calibrate via S3.5
A30: FPPTREV Group | B30: S3.1 | C30: Federal Personal Payroll Tax Revenue by Group | D30: FPPTREV_amer_i = AIAVG_amer_i * EP_amer_i * PARAMETERS!FED_PAYROLL_RATE; FPPTREV_auth_i = AIAVG_auth_i * EP_auth_i * PARAMETERS!FED_PAYROLL_RATE; FPPTREV_unauth_i = AIAVG_unauth_i * EP_unauth_i * PARAMETERS!FED_PAYROLL_RATE_UNAUTH; FPPTREV_total_i = FPPTREV_auth_i + FPPTREV_unauth_i + FPPTREV_amer_i | E30: SS/Medicare 7.65%; unauth partial 0.05 | F30: 90% accuracy; fiscal calibration post-sum
A31: EITCREF Group | B31: S3.2 | C31: EITC Credit Refund by Group | D31: EITCREF_amer_i = PARAMETERS!EITC_TOTAL_REFUND_AL * (EP_amer_i / PARAMETERS!TOTAL_NONFARM_AL) * PARAMETERS!EITC_ELIG_FACTOR_AMER_IND[i]; EITCREF_auth_i = PARAMETERS!EITC_TOTAL_REFUND_AL * (EP_auth_i / PARAMETERS!TOTAL_NONFARM_AL) * PARAMETERS!EITC_ELIG_FACTOR_AUTH_IND[i]; EITCREF_unauth_i = 0; EITCREF_total_i = EITCREF_auth_i + EITCREF_amer_i | E31: Prorate IRS total by eligibility factors (unauth 0, auth 0.8-1.0 industry-varied) | F31: Blend IRS (0.5), TPC (0.3), Urban (0.2); 95% accuracy; unauth ineligible
A32: ACTCREF Group | B32: S3.3 | C32: Additional Child Tax Credit Refund by Group | D32: ACTCREF_amer_i = PARAMETERS!ACTC_TOTAL_REFUND_AL * (EP_amer_i / PARAMETERS!TOTAL_NONFARM_AL) * PARAMETERS!ACTC_ELIG_FACTOR_AMER_IND[i]; ACTCREF_auth_i = PARAMETERS!ACTC_TOTAL_REFUND_AL * (EP_auth_i / PARAMETERS!TOTAL_NONFARM_AL) * PARAMETERS!ACTC_ELIG_FACTOR_AUTH_IND[i]; ACTCREF_unauth_i = PARAMETERS!ACTC_TOTAL_REFUND_AL * (EP_unauth_i / PARAMETERS!TOTAL_NONFARM_AL) * PARAMETERS!ACTC_ELIG_FACTOR_UNAUTH_IND[i]; ACTCREF_total_i = sum by group | E32: Prorate IRS; unauth partial 0.5 via ITIN | F32: 85% accuracy; industry-varied eligibility
A33: AOTCREF Group | B33: S3.4 | C33: American Opportunity Tax Credit Refund by Group | D33: AOTCREF_amer_i = PARAMETERS!AOTC_TOTAL_REFUND_AL * (EP_amer_i / PARAMETERS!TOTAL_NONFARM_AL) * PARAMETERS!AOTC_ELIG_FACTOR_AMER_IND[i]; AOTCREF_auth_i = PARAMETERS!AOTC_TOTAL_REFUND_AL * (EP_auth_i / PARAMETERS!TOTAL_NONFARM_AL) * PARAMETERS!AOTC_ELIG_FACTOR_AUTH_IND[i]; AOTCREF_unauth_i = PARAMETERS!AOTC_TOTAL_REFUND_AL * (EP_unauth_i / PARAMETERS!TOTAL_NONFARM_AL) * PARAMETERS!AOTC_ELIG_FACTOR_UNAUTH_IND[i]; AOTCREF_total_i = sum by group | E33: Prorate IRS; unauth low 0.3 (education barriers) | F33: 90% accuracy
A34: S3 - Fiscal Calibration | B34: S3.5 | C34: Fiscal Calibration | D34: FPITREV_state_total = raw_FPITREV_state_total * PARAMETERS!FISCAL_CALIBRATION_SCALE; same for FPPTREV, SLTR, SSMC | E34: Scale fiscal aggregates to IRS/BEA totals | F34: Improves fiscal realism post-calc; new addition for better net fiscal validation
A35: S4 - Derived | B35: S4 | C35: Shared - Other Metrics | D35: AWHW_total_i = PARAMETERS!AWHW_IND[i]; AWHW_auth_i = AWHW_total_i * PARAMETERS!IMMIGRANT_AWHW_FACTOR; AWHW_unauth_i = AWHW_total_i * PARAMETERS!UNAUTH_AWHW_FACTOR; AWHW_amer_i = (AWHW_total_i * EP_total_i - AWHW_auth_i * EP_auth_i - AWHW_unauth_i * EP_unauth_i) / EP_amer_i | E35: BLS industry avg hours; immigrants often higher (+5%) | F35: 95% accuracy; adjusted factors down
A36: S4 - Derived | B36: S4.0 | C36: Average Weekly Hours Worked by Group | D36: AWHW_amer_i = PARAMETERS!AWHW_IND_AMER[i]; AWHW_auth_i = AWHW_amer_i * PARAMETERS!IMMIGRANT_AWHW_FACTOR_IND[i]; AWHW_unauth_i = AWHW_amer_i * PARAMETERS!UNAUTH_AWHW_FACTOR_IND[i]; AWHW_total_i = (AWHW_auth_i * EP_auth_i + AWHW_unauth_i * EP_unauth_i + AWHW_amer_i * EP_amer_i) / EP_total_i | E36: BLS industry avg hours; immigrants often higher (+5%) industry-varied | F36: 95% accuracy; blend sources; edited to AWHW_i = PARAMETERS!BASE_AWHW_IND[i] * (1 + PARAMETERS!SEASONAL_HOURS_FACTOR[i])
... A45: S4 - Derived | B45: S4.9 | C45: Public Assistance Usage Rate by Group | D45: PAUR_amer_i = PARAMETERS!PAUR_IND_AMER[i]; PAUR_auth_i = PAUR_amer_i * PARAMETERS!IMMIGRANT_PAUR_FACTOR_IND[i]; PAUR_unauth_i = PAUR_amer_i * PARAMETERS!UNAUTH_PAUR_FACTOR_IND[i]; PAUR_total_i = (PAUR_auth_i * POP_auth_i + PAUR_unauth_i * POP_unauth_i + PAUR_amer_i * POP_amer_i) / POP_total_i | E45: Census/CMS usage %; unauth lower eligibility (0.5x) | F45: 80% accuracy; challenging data; edited to use increased PAUR_ADJ_FACTOR (P047) for SNAP match ~14.5%
A46: 300 - Aggregate | B46: 300 | C46: Aggregate / Summary / Weighted Average Formulae | D46: LFP_state_total = SUM(CALC!LFP_total_i for all) * PARAMETERS!CALIBRATION_SCALE_LFP | E46: Direct sum scaled to BLS target | F46: Should = P120; if scale >1.05 or <0.95, flag for review
A47: 300 - Aggregate | B47: 300 | C47: Total Labor Force Population – Statewide | D47: LFP_state_total = SUM(CALC!LFP_total_i) * PARAMETERS!CALIBRATION_SCALE_LFP | E47: Sum scaled to BLS | F47: 0
A48: 300 - Aggregate | B48: 300.1 | C48: Total Authorized Labor Force Population – Statewide | D48: LFP_state_auth = SUM(CALC!LFP_auth_i) | E48: Sum authorized | F48: Target ~120k
A49: 300 - Aggregate | B49: 300.2 | C49: Total Unauthorized Labor Force Population – Statewide | D49: LFP_state_unauth = SUM(CALC!LFP_unauth_i) * (PARAMETERS!UNAUTH_REAL_LF_EST / raw_unauth_sum) | E49: Scaled to MPI | F49: Target 55k
A50: 300 - Aggregate | B50: 300.3 | C50: Total American Labor Force Population – Statewide | D50: LFP_state_amer = SUM(CALC!LFP_amer_i) | E50: Sum American | F50: Residual
A51: 300 - Aggregate | B51: 300.6 | C51: Weighted Average Unemployment Rate (U3R) – Statewide | D51: U3R_state_weighted = SUM(CALC!U3R_total_i * CALC!LFP_total_i) / SUM(CALC!LFP_total_i) * PARAMETERS!CALIBRATION_SCALE_U3R | E51: Weighted & scaled | F51: 0
A52: 300 - Aggregate | B52: 300.8 | C52: Weighted Average Wage ($/hr) – Statewide | D52: WAVG_state_weighted = SUM(CALC!WAVG_total_i * CALC!EP_total_i) / SUM(CALC!EP_total_i) | E52: Weighted by EP | F52: 0
...

Sheet PARAM
A1: LSD.REF.AL.PARAM | B1: Alabama Labor Statistic Logic Parameters | C1: December 2025
A2: P001 | B2: TOTAL_NONFARM_AL | C2: 2211 | D2: AL / Total nonfarm payroll employment (thousands) | E2: BLS CES December 2025 preliminary (proxy for Jan 2026) | F2: High | G2: BLS CES release January 2026 | H2: February 2026
A3: P002 | B3: AG_EMPLOYMENT_AL | C3: 33 | D3: AL / Agriculture employment (thousands) | E3: BLS CES + ACS self-employed adjustment + modest growth | F3: Medium | G3: BLS CES Dec 2025 + ACS 2024 est. + growth | H3: February 2026
A4: P003 | B4: CONSTR_EMPLOYMENT_AL | C4: 112 | D4: AL / Construction employment (thousands) | E4: BLS CES December 2025 preliminary | F4: High | G4: BLS CES January 2026 | H4: February 2026
A5: P004 | B5: MANU_EMPLOYMENT_AL | C5: 287 | D5: AL / Manufacturing employment (thousands) | E5: BLS CES December 2025 preliminary | F5: High | G5: BLS CES January 2026 | H5: February 2026
A6: P005 | B6: TRADE_TRANS_UTIL_EMPLOYMENT_AL | C6: 408 | D6: AL / Trade, Transportation, Utilities (thousands) | E6: BLS CES December 2025 preliminary | F6: High | G6: BLS CES January 2026 | H6: February 2026
A7: P006 | B7: INFO_EMPLOYMENT_AL | C7: 23 | D7: AL / Information employment (thousands) | E7: BLS CES December 2025 preliminary | F7: High | G7: BLS CES January 2026 | H7: February 2026
A8: P007 | B8: FIN_EMPLOYMENT_AL | C8: 101 | D8: AL / Financial Activities employment (thousands) | E8: BLS CES December 2025 preliminary | F8: High | G8: BLS CES January 2026 | H8: February 2026
A9: P008 | B9: PROF_BUS_EMPLOYMENT_AL | C9: 261 | D9: AL / Professional and Business Services (thousands) | E9: BLS CES December 2025 preliminary | F9: High | G9: BLS CES January 2026 | H9: February 2026
A10: P009 | B10: ED_HEALTH_EMPLOYMENT_AL | C10: 273 | D10: AL / Education and Health Services (thousands) | E10: BLS CES December 2025 preliminary | F10: High | G10: BLS CES January 2026 | H10: February 2026
A11: P010 | B11: LEIS_HOSP_EMPLOYMENT_AL | C11: 217 | D11: AL / Leisure and Hospitality employment (thousands) | E11: BLS CES December 2025 preliminary | F11: High | G11: BLS CES January 2026 | H11: February 2026
A12: P011 | B12: OTHER_SERV_EMPLOYMENT_AL | C12: 99 | D12: AL / Other Services employment (thousands) | E12: BLS CES December 2025 preliminary | F12: High | G12: BLS CES January 2026 | H12: February 2026
A13: P012 | B13: GOV_EMPLOYMENT_AL | C13: 421 | D13: AL / Government employment (thousands) | E13: BLS CES December 2025 preliminary | F13: High | G13: BLS CES January 2026 | H13: February 2026
... A52: P072 | B52: CALIBRATION_SCALE_EP | C52: 1 | D52: Default employment calibration scalar | E52: Overridden by FID 500.0 formula | F52: High | G52: Internal | H52: February 2026
A53: Shared Parameters Table (for PARAM tab)
A54: PID | B54: Parameter Name | C54: Value | D54: State / Description | E54: Notes / Sources | F54: Confidence Rating | G54: Confidence Source Note | H54: Last Updated / Source Note
A55: P001 | B55: TOTAL_NONFARM_AL | C55: 2211 | D55: AL / Total nonfarm payroll employment (thousands) | E55: BLS CES December 2025 preliminary (proxy for Jan 2026) | F55: High | G55: BLS CES release January 2026 | H55: February 2026
A56: P002 | B56: AG_EMPLOYMENT_AL | C56: 33 | D56: AL / Agriculture employment (thousands) | E56: BLS CES + ACS self-employed adjustment + modest growth | F56: Medium | G56: BLS CES Dec 2025 + ACS 2024 est. + growth | H56: February 2026
A57: P003 | B57: CONSTR_EMPLOYMENT_AL | C57: 112 | D57: AL / Construction employment (thousands) | E57: BLS CES December 2025 preliminary | F57: High | G57: BLS CES January 2026 | H57: February 2026
A58: P004 | B58: MANU_EMPLOYMENT_AL | C58: 287 | D58: AL / Manufacturing employment (thousands) | E58: BLS CES December 2025 preliminary | F58: High | G58: BLS CES January 2026 | H58: February 2026
A59: P005 | B59: TRADE_TRANS_UTIL_EMPLOYMENT_AL | C59: 408 | D59: AL / Trade, Transportation, Utilities (thousands) | E59: BLS CES December 2025 preliminary | F59: High | G59: BLS CES January 2026 | H59: February 2026
A60: P006 | B60: INFO_EMPLOYMENT_AL | C60: 23 | D60: AL / Information employment (thousands) | E60: BLS CES December 2025 preliminary | F60: High | G60: BLS CES January 2026 | H60: February 2026
A61: P007 | B61: FIN_EMPLOYMENT_AL | C61: 101 | D61: AL / Financial Activities employment (thousands) | E61: BLS CES December 2025 preliminary | F61: High | G61: BLS CES January 2026 | H61: February 2026
A62: P008 | B62: PROF_BUS_EMPLOYMENT_AL | C62: 261 | D62: AL / Professional and Business Services (thousands) | E62: BLS CES December 2025 preliminary | F62: High | G62: BLS CES January 2026 | H62: February 2026
A63: P009 | B63: ED_HEALTH_EMPLOYMENT_AL | C63: 273 | D63: AL / Education and Health Services (thousands) | E63: BLS CES December 2025 preliminary | F63: High | G63: BLS CES January 2026 | H63: February 2026
A64: P010 | B64: LEIS_HOSP_EMPLOYMENT_AL | C64: 217 | D64: AL / Leisure and Hospitality employment (thousands) | E64: BLS CES December 2025 preliminary | F64: High | G64: BLS CES January 2026 | H64: February 2026
A65: P011 | B65: OTHER_SERV_EMPLOYMENT_AL | C65: 99 | D65: AL / Other Services employment (thousands) | E65: BLS CES December 2025 preliminary | F65: High | G65: BLS CES January 2026 | H65: February 2026
A66: P012 | B66: GOV_EMPLOYMENT_AL | C66: 421 | D66: AL / Government employment (thousands) | E66: BLS CES December 2025 preliminary | F66: High | G66: BLS CES January 2026 | H66: February 2026
... A124: P091 | B124: IMMIGRANT_LFPR_ADJ | C124: 0.05 | D124: Authorized immigrant LFPR adjustment factor (new addition for S7) | E124: Slightly higher than American | F124: Medium | G124: ACS | H124: February 2026
A126: LFP Parameters
A127: PID | B127: Parameter Name | C127: Value | D127: State / Description | E127: Notes / Sources | F127: Confidence Rating | G127: Confidence Source Note | H127: Last Updated / Source Note
A128: LFP.0 | B128: BLS_LFP_TOTAL_TARGET | C128: 2384 | D128: AL / Total labor force population target (thousands) | E128: BLS LAUS December 2025 preliminary; matches CALC aggregate ~2,384k | F128: High | G128: BLS LAUS January 2026 | H128: February 2026
A129: LFP.1 | B129: LFP_CALIBRATION_FACTOR_AG | C129: 1.05 | D129: Industry-specific LFP calibration – Agriculture | E129: Higher for seasonal/self-employed; edited per VALID V004 for better match | F129: Medium | G129: ACS 2024 + BLS adjustment | H129: February 2026
A130: LFP.2 | B130: UNAUTH_IMMIGRANT_LFP_ADJ_FACTOR | C130: 1.1 | D130: Unauthorized immigrant LFP adjustment factor | E130: Higher participation est.; used in LFP.2 formula | F130: Medium | G130: MPI / ACS consensus | H130: February 2026
A131: LFP.3 | B131: AUTH_IMMIGRANT_LFP_ADJ_FACTOR | C131: 1.03 | D131: Authorized immigrant LFP adjustment factor | E131: Slightly higher than American; used in LFP.1 formula | F131: Medium | G131: ACS 2024 | H131: February 2026
A132: LFP.4 | B132: LFP_PRORATE_FACTOR_CONSTR | C132: 1.02 | D132: Proration factor for LFP – Construction | E132: Minor uplift for volatile employment; used in LFP.4 formula | F132: High | G132: BLS CES / LAUS | H132: February 2026
A133: LFP.5 | B133: LFP_PRORATE_FACTOR_MANU | C133: 0.98 | D133: Proration factor for LFP – Manufacturing | E133: Slight downward for stable sector; used in LFP.4 formula | F133: High | G133: BLS CES / LAUS | H133: February 2026
A135: LFPR Parameters
A136: PID | B136: Parameter Name | C136: Value | D136: State / Description | E136: Notes / Sources | F136: Confidence Rating | G136: Confidence Source Note | H136: Last Updated / Source Note
A137: LFPR.0 | B137: BLS_LFPR_TARGET | C137: 0.577 | D137: AL / Statewide Labor Force Participation Rate target | E137: BLS LAUS December 2025 seasonally adjusted: 57.7%; matches AL DOL / FRED data | F137: High | G137: BLS LAUS / FRED LBSSA01 January 2026 release | H137: February 2026
...

Sheet CALC
A1: LSD.RID.0.AL.CALC | B1: Alabama Labor Statistic Calculations | C1: December 2025
A2: Labor Industry Role (LIR) | D2: Labor Force Population (LFP) | H2: Employment-to-Population Ratio (ETPR) | L2: Labor Force Participation Rate (LFPR) | P2: Unemployment Rate (U3R) | T2: Underemployment Rate (U6R) | X2: Wage Average (WAVG) | AA2: Annual Income Average (AIAVG) | AD2: Authorized Immigrant Wage Average (AIWAVG) | AG2: Authorized Immigrant Annual Income Average (AIAIAVG) | AJ2: Unauthorized Immigrant Wage Average (UIWAVG) | AM2: Unauthorized Immigrant Annual Income Average (UIAIAVG) | AP2: American Wage Average (AWAVG) | AS2: American Annual Income Average (AAIAVG) | AV2: Federal Personal Income Tax Revenue (FPITREV) | AZ2: Federal Personal Payroll Tax Revenue (FPPTREV) | BD2: Earned Income Tax Credit Refund (EITCREF) | BH2: Additional Child Tax Credit Refund (ACTCREF) | BL2: American Opportunity Tax Credit Refund (AOTCREF) | BP2: Employed Population (EP) | BT2: Average Weekly Hours Worked (AWHW) | BZ2: Full-Time Employment Rate (FTER) | CD2: Part-Time Employment Rate (PTER) | CH2: Job Tenure Average (JTA) | CN2: Turnover Rate (TR) | CR2: Labor Productivity (LP) | CV2: Education Level Required (ELR) | CZ2: State/Local Tax Revenue (SLTR) | DD2: Social Security/Medicare Contributions (SSMC) | DH2: Public Assistance Usage Rate (PAUR)
A3: Labor Industry Role (LIR) | B3: Labor Industry | C3: Role Level | D3: Labor Force Population | E3: Authorized Labor Force Population | F3: Unauthorized Labor Force Population | G3: American Labor Force Population | H3: Employment-to-Population Ratio | I3: Authorized Immigrant Employment-to-Population Ratio | J3: Unauthorized Immigrant Employment-to-Population Ratio | K3: American Employment-to-Population Ratio | L3: Labor Force Participation Rate (LFPR) | M3: Authorized Immigrant Labor Force Participation Rate (LFPR) | N3: Unauthorized Immigrant Labor Force Participation Rate (LFPR) | O3: American Labor Force Participation Rate (LFPR) | P3: Unemployment Rate | Q3: Authorized Immigrant Unemployment Rate | R3: Unauthorized Immigrant Unemployment Rate | S3: American Unemployment Rate | T3: Underemployment Rate | U3: Authorized Immigrant Underemployment Rate | V3: Unauthorized Immigrant Underemployment Rate | W3: American Underemployment Rate | X3: Wage Average ($ /hr) | Y3: Wage Min ($ /hr) | Z3: Wage Max ($ /hr) | AA3: Annual Income Average ($) | AB3: Annual Income Min ($) | AC3: Annual Income Max ($) | AD3: Authorized Immigrant Wage Average ($ /hr) | AE3: Authorized Immigrant Wage Min ($ /hr) | AF3: Authorized Immigrant Wage Max ($ /hr) | AG3: Authorized Immigrant Annual Income Average ($) | AH3: Authorized Immigrant Annual Income Min ($) | AI3: Authorized Immigrant Annual Income Max ($) | AJ3: Unauthorized Immigrant Wage Average ($ /hr) | AK3: Unauthorized Immigrant Wage Min ($ /hr) | AL3: Unauthorized Immigrant Wage Max ($ /hr) | AM3: Unauthorized Immigrant Annual Income Average ($) | AN3: Unauthorized Immigrant Annual Income Min ($) | AO3: Unauthorized Immigrant Annual Income Max ($) | AP3: American Wage Average ($ /hr) | AQ3: American Wage Min ($ /hr) | AR3: American Wage Max ($ /hr) | AS3: American Annual Income Average ($) | AT3: American Annual Income Min ($) | AU3: American Annual Income Max ($) | AV3: Federal Personal Income Tax Revenue ($) | AW3: Authorized Immigrant Federal Personal Income Tax Revenue ($) | AX3: Unauthorized Immigrant Federal Personal Income Tax Revenue ($) | AY3: American Federal Personal Income Tax Revenue ($) | AZ3: Payroll Tax Revenue ($) | BA3: Authorized Immigrant Payroll Tax Revenue ($) | BB3: Unauthorized Immigrant Payroll Tax Revenue ($) | BC3: American Payroll Tax Revenue ($) | BD3: EITC Credit Refund | BE3: Authorized Immigrant EITC Credit Refund | BF3: Unauthorized Immigrant EITC Credit Refund | BG3: American EITC Refund | BH3: ACTC Refund | BI3: Authorized Immigrant ACTC Refund | BJ3: Unauthorized Immigrant ACTC Refund | BK3: American Tax ACTC Refund | BL3: AOTC Refund | BM3: Authorized Immigrant AOTC Refund | BN3: Unauthorized Immigrant AOTC Refund | BO3: American Tax AOTC Refund | BP3: Employed Population | BQ3: Authorized Immigrant Employed Population | BR3: Unauthorized Immigrant Employed Population | BS3: American Employed Population | BT3: Average Weekly Hours Worked | BU3: Authorized Immigrant Average Weekly Hours Worked | BV3: Unauthorized Immigrant Average Weekly Hours Worked | BW3: American Average Weekly Hours Worked | BX3: AWHW Min Hours | BY3: AWHW Max Hours | BZ3: Full-Time Employment Rate | CA3: Authorized Immigrant Full-Time Employment Rate | CB3: Unauthorized Immigrant Full-Time Employment Rate | CC3: American Full-Time Employment Rate | CD3: Part-Time Employment Rate | CE3: Authorized Immigrant Part-Time Employment Rate | CF3: Unauthorized Immigrant Part-Time Employment Rate | CG3: American Part-Time Employment Rate | CH3: Job Tenure Average (years) | CI3: Authorized Immigrant Job Tenure Average | CJ3: Unauthorized Immigrant Job Tenure Average | CK3: American Job Tenure Average | CL3: JTA Min Tenure | CM3: JTA Max Tenure | CN3: Turnover Rate | CO3: Authorized Immigrant Turnover Rate | CP3: Unauthorized Immigrant Turnover Rate | CQ3: American Turnover Rate | CR3: Labor Productivity ($/hr) | CS3: Authorized Immigrant Labor Productivity | CT3: Unauthorized Immigrant Labor Productivity | CU3: American Labor Productivity | CV3: Education Level Required Average | CW3: Authorized Immigrant Education Level Average | CX3: Unauthorized Immigrant Education Level Average | CY3: American Education Level Average | CZ3: State/Local Tax Revenue ($) | DA3: Authorized Immigrant State/Local Tax Revenue | DB3: Unauthorized Immigrant State/Local Tax Revenue | DC3: American State/Local Tax Revenue | DD3: Social Security/Medicare Contributions ($) | DE3: Authorized Immigrant Social Security/Medicare Contributions | DF3: Unauthorized Immigrant Social Security/Medicare Contributions | DG3: American Social Security/Medicare Contributions | DH3: Public Assistance Usage Rate | DI3: Authorized Immigrant Public Assistance Usage Rate | DJ3: Unauthorized Immigrant Public Assistance Usage Rate | DK3: American Public Assistance Usage Rate
A4: 0 | B4: All Industries | C4: All Roles
A5: 1 | B5: Agriculture | C5: Support
A6: 2 | B6: Agriculture | C6: Worker
A7: 3 | B7: Construction | C7: Support
A8: 4 | B8: Construction | C8: Worker
A9: 5 | B9: Hospitality | C9: Support
A10: 6 | B10: Hospitality | C10: Worker
A11: 7 | B11: Cleaning & Maintenance | C11: Support
A12: 8 | B12: Cleaning & Maintenance | C12: Worker
A13: 9 | B13: Manufacturing | C13: Support
A14: 10 | B14: Manufacturing | C14: Worker
A15: 11 | B15: Transportation & Warehousing | C15: Support
... A56: 52 | B56: Public Administration | C56: Worker

Sheet VALID
A1: LSD.RID.0.AL.VALID | B1: Alabama Labor Statistic Calculation Validation | C1: December 2025
A2: VALID | B2: Metric | C2: Calculated Value | D2: Public Value | E2: Source | F2: Validation Rating | G2: Notes/Improvement

Sheet LFP
A1: LSD.RID.0.AL.LFP | B1: Alabama Labor Force Population (LFP) | C1: December 2025 | D1: Authorized, Unauthorized, American Labor Force Population By Industrial Labor Role
A2: LIRVID | B2: Industry: Role | C2: =CALC!D3 -> Labor Force Population | D2: =CALC!E3 -> Authorized Labor Force Population | E2: =CALC!F3 -> Unauthorized Labor Force Population | F2: =CALC!G3 -> American Labor Force Population
A3: =_xlfn.CONCAT($A$1, ".", CALC!A4) -> LSD.RID.0.AL.LFP.0 | B3: =_xlfn.CONCAT(CALC!B4, ":", CALC!C4) -> All Industries:All Roles | C3: =CALC!D4 -> 0 | D3: =CALC!E4 -> 0 | E3: =CALC!F4 -> 0 | F3: =CALC!G4 -> 0
A4: =_xlfn.CONCAT($A$1, ".", CALC!A5) -> LSD.RID.0.AL.LFP.1 | B4: =_xlfn.CONCAT(CALC!B5, ": ", CALC!C5) -> Agriculture: Support | C4: =CALC!D5 -> 0 | D4: =CALC!E5 -> 0 | E4: =CALC!F5 -> 0 | F4: =CALC!G5 -> 0
A5: =_xlfn.CONCAT($A$1, ".", CALC!A6) -> LSD.RID.0.AL.LFP.2 | B5: =_xlfn.CONCAT(CALC!B6, ": ", CALC!C6) -> Agriculture: Worker | C5: =CALC!D6 -> 0 | D5: =CALC!E6 -> 0 | E5: =CALC!F6 -> 0 | F5: =CALC!G6 -> 0
A6: =_xlfn.CONCAT($A$1, ".", CALC!A7) -> LSD.RID.0.AL.LFP.3 | B6: =_xlfn.CONCAT(CALC!B7, ": ", CALC!C7) -> Construction: Support | C6: =CALC!D7 -> 0 | D6: =CALC!E7 -> 0 | E6: =CALC!F7 -> 0 | F6: =CALC!G7 -> 0
A7: =_xlfn.CONCAT($A$1, ".", CALC!A8) -> LSD.RID.0.AL.LFP.4 | B7: =_xlfn.CONCAT(CALC!B8, ": ", CALC!C8) -> Construction: Worker | C7: =CALC!D8 -> 0 | D7: =CALC!E8 -> 0 | E7: =CALC!F8 -> 0 | F7: =CALC!G8 -> 0
A8: =_xlfn.CONCAT($A$1, ".", CALC!A9) -> LSD.RID.0.AL.LFP.5 | B8: =_xlfn.CONCAT(CALC!B9, ": ", CALC!C9) -> Hospitality: Support | C8: =CALC!D9 -> 0 | D8: =CALC!E9 -> 0 | E8: =CALC!F9 -> 0 | F8: =CALC!G9 -> 0
A9: =_xlfn.CONCAT($A$1, ".", CALC!A10) -> LSD.RID.0.AL.LFP.6 | B9: =_xlfn.CONCAT(CALC!B10, ": ", CALC!C10) -> Hospitality: Worker | C9: =CALC!D10 -> 0 | D9: =CALC!E10 -> 0 | E9: =CALC!F10 -> 0 | F9: =CALC!G10 -> 0
A10: =_xlfn.CONCAT($A$1, ".", CALC!A11) -> LSD.RID.0.AL.LFP.7 | B10: =_xlfn.CONCAT(CALC!B11, ": ", CALC!C11) -> Cleaning & Maintenance: Support | C10: =CALC!D11 -> 0 | D10: =CALC!E11 -> 0 | E10: =CALC!F11 -> 0 | F10: =CALC!G11 -> 0
A11: =_xlfn.CONCAT($A$1, ".", CALC!A12) -> LSD.RID.0.AL.LFP.8 | B11: =_xlfn.CONCAT(CALC!B12, ": ", CALC!C12) -> Cleaning & Maintenance: Worker | C11: =CALC!D12 -> 0 | D11: =CALC!E12 -> 0 | E11: =CALC!F12 -> 0 | F11: =CALC!G12 -> 0
A12: =_xlfn.CONCAT($A$1, ".", CALC!A13) -> LSD.RID.0.AL.LFP.9 | B12: =_xlfn.CONCAT(CALC!B13, ": ", CALC!C13) -> Manufacturing: Support | C12: =CALC!D13 -> 0 | D12: =CALC!E13 -> 0 | E12: =CALC!F13 -> 0 | F12: =CALC!G13 -> 0
A13: =_xlfn.CONCAT($A$1, ".", CALC!A14) -> LSD.RID.0.AL.LFP.10 | B13: =_xlfn.CONCAT(CALC!B14, ": ", CALC!C14) -> Manufacturing: Worker | C13: =CALC!D14 -> 0 | D13: =CALC!E14 -> 0 | E13: =CALC!F14 -> 0 | F13: =CALC!G14 -> 0
A14: =_xlfn.CONCAT($A$1, ".", CALC!A15) -> LSD.RID.0.AL.LFP.11 | B14: =_xlfn.CONCAT(CALC!B15, ": ", CALC!C15) -> Transportation & Warehousing: Support | C14: =CALC!D15 -> 0 | D14: =CALC!E15 -> 0 | E14: =CALC!F15 -> 0 | F14: =CALC!G15 -> 0
A15: =_xlfn.CONCAT($A$1, ".", CALC!A16) -> LSD.RID.0.AL.LFP.12 | B15: =_xlfn.CONCAT(CALC!B16, ": ", CALC!C16) -> Transportation & Warehousing: Worker | C15: =CALC!D16 -> 0 | D15: =CALC!E16 -> 0 | E15: =CALC!F16 -> 0 | F15: =CALC!G16 -> 0
... A55: =_xlfn.CONCAT($A$1, ".", CALC!A56) -> LSD.RID.0.AL.LFP.52 | B55: =_xlfn.CONCAT(CALC!B56, ": ", CALC!C56) -> Public Administration: Worker | C55: =CALC!D56 -> 0 | D55: =CALC!E56 -> 0 | E55: =CALC!F56 -> 0 | F55: =CALC!G56 -> 0

Sheet ETPR
A1: LSD.RID.0.AL.ETPR | B1: Alabama Employment-to-Population Ratio (ETPR) | C1: December 2025 | D1: Authorized, Unauthorized, American Laborer Employment-to-Population Ratio By Industrial Labor Role
A2: LIRVID | B2: Industry: Role | C2: =CALC!H3 -> Employment-to-Population Ratio | D2: =CALC!I3 -> Authorized Immigrant Employment-to-Population Ratio | E2: =CALC!J3 -> Unauthorized Immigrant Employment-to-Population Ratio | F2: =CALC!K3 -> American Employment-to-Population Ratio
A3: =_xlfn.CONCAT($A$1, ".", CALC!A4) -> LSD.RID.0.AL.ETPR.0 | B3: =_xlfn.CONCAT(CALC!B4, ":", CALC!C4) -> All Industries:All Roles | C3: =CALC!H4 -> 0 | D3: =CALC!I4 -> 0 | E3: =CALC!J4 -> 0 | F3: =CALC!K4 -> 0
A4: =_xlfn.CONCAT($A$1, ".", CALC!A5) -> LSD.RID.0.AL.ETPR.1 | B4: =_xlfn.CONCAT(CALC!B5, ": ", CALC!C5) -> Agriculture: Support | C4: =CALC!H5 -> 0 | D4: =CALC!I5 -> 0 | E4: =CALC!J5 -> 0 | F4: =CALC!K5 -> 0
A5: =_xlfn.CONCAT($A$1, ".", CALC!A6) -> LSD.RID.0.AL.ETPR.2 | B5: =_xlfn.CONCAT(CALC!B6, ": ", CALC!C6) -> Agriculture: Worker | C5: =CALC!H6 -> 0 | D5: =CALC!I6 -> 0 | E5: =CALC!J6 -> 0 | F5: =CALC!K6 -> 0
A6: =_xlfn.CONCAT($A$1, ".", CALC!A7) -> LSD.RID.0.AL.ETPR.3 | B6: =_xlfn.CONCAT(CALC!B7, ": ", CALC!C7) -> Construction: Support | C6: =CALC!H7 -> 0 | D6: =CALC!I7 -> 0 | E6: =CALC!J7 -> 0 | F6: =CALC!K7 -> 0
A7: =_xlfn.CONCAT($A$1, ".", CALC!A8) -> LSD.RID.0.AL.ETPR.4 | B7: =_xlfn.CONCAT(CALC!B8, ": ", CALC!C8) -> Construction: Worker | C7: =CALC!H8 -> 0 | D7: =CALC!I8 -> 0 | E7: =CALC!J8 -> 0 | F7: =CALC!K8 -> 0
A8: =_xlfn.CONCAT($A$1, ".", CALC!A9) -> LSD.RID.0.AL.ETPR.5 | B8: =_xlfn.CONCAT(CALC!B9, ": ", CALC!C9) -> Hospitality: Support | C8: =CALC!H9 -> 0 | D8: =CALC!I9 -> 0 | E8: =CALC!J9 -> 0 | F8: =CALC!K9 -> 0
A9: =_xlfn.CONCAT($A$1, ".", CALC!A10) -> LSD.RID.0.AL.ETPR.6 | B9: =_xlfn.CONCAT(CALC!B10, ": ", CALC!C10) -> Hospitality: Worker | C9: =CALC!H10 -> 0 | D9: =CALC!I10 -> 0 | E9: =CALC!J10 -> 0 | F9: =CALC!K10 -> 0
A10: =_xlfn.CONCAT($A$1, ".", CALC!A11) -> LSD.RID.0.AL.ETPR.7 | B10: =_xlfn.CONCAT(CALC!B11, ": ", CALC!C11) -> Cleaning & Maintenance: Support | C10: =CALC!H11 -> 0 | D10: =CALC!I11 -> 0 | E10: =CALC!J11 -> 0 | F10: =CALC!K11 -> 0
A11: =_xlfn.CONCAT($A$1, ".", CALC!A12) -> LSD.RID.0.AL.ETPR.8 | B11: =_xlfn.CONCAT(CALC!B12, ": ", CALC!C12) -> Cleaning & Maintenance: Worker | C11: =CALC!H12 -> 0 | D11: =CALC!I12 -> 0 | E11: =CALC!J12 -> 0 | F11: =CALC!K12 -> 0
A12: =_xlfn.CONCAT($A$1, ".", CALC!A13) -> LSD.RID.0.AL.ETPR.9 | B12: =_xlfn.CONCAT(CALC!B13, ": ", CALC!C13) -> Manufacturing: Support | C12: =CALC!H13 -> 0 | D12: =CALC!I13 -> 0 | E12: =CALC!J13 -> 0 | F12: =CALC!K13 -> 0
A13: =_xlfn.CONCAT($A$1, ".", CALC!A14) -> LSD.RID.0.AL.ETPR.10 | B13: =_xlfn.CONCAT(CALC!B14, ": ", CALC!C14) -> Manufacturing: Worker | C13: =CALC!H14 -> 0 | D13: =CALC!I14 -> 0 | E13: =CALC!J14 -> 0 | F13: =CALC!K14 -> 0
A14: =_xlfn.CONCAT($A$1, ".", CALC!A15) -> LSD.RID.0.AL.ETPR.11 | B14: =_xlfn.CONCAT(CALC!B15, ": ", CALC!C15) -> Transportation & Warehousing: Support | C14: =CALC!H15 -> 0 | D14: =CALC!I15 -> 0 | E14: =CALC!J15 -> 0 | F14: =CALC!K15 -> 0
A15: =_xlfn.CONCAT($A$1, ".", CALC!A16) -> LSD.RID.0.AL.ETPR.12 | B15: =_xlfn.CONCAT(CALC!B16, ": ", CALC!C16) -> Transportation & Warehousing: Worker | C15: =CALC!H16 -> 0 | D15: =CALC!I16 -> 0 | E15: =CALC!J16 -> 0 | F15: =CALC!K16 -> 0
... A55: =_xlfn.CONCAT($A$1, ".", CALC!A56) -> LSD.RID.0.AL.ETPR.52 | B55: =_xlfn.CONCAT(CALC!B56, ": ", CALC!C56) -> Public Administration: Worker | C55: =CALC!H56 -> 0 | D55: =CALC!I56 -> 0 | E55: =CALC!J56 -> 0 | F55: =CALC!K56 -> 0

Sheet LFPR
A1: LSD.RID.0.AL.LFPR | B1: Alabama Labor Force Participation Rate (LFPR) | C1: December 2025 | D1: Labor Force Participation Rate (ETPR) | E1: Authorized, Unauthorized, American Laborer Labor Force Participation Rate By Industrial Labor Role
A2: LIRVID | B2: Industry: Role | C2: =CALC!L3 -> Labor Force Participation Rate (LFPR) | D2: =CALC!M3 -> Authorized Immigrant Labor Force Participation Rate (LFPR) | E2: =CALC!N3 -> Unauthorized Immigrant Labor Force Participation Rate (LFPR) | F2: =CALC!O3 -> American Labor Force Participation Rate (LFPR)
A3: =_xlfn.CONCAT($A$1, ".", CALC!A4) -> LSD.RID.0.AL.LFPR.0 | B3: =_xlfn.CONCAT(CALC!B4, ":", CALC!C4) -> All Industries:All Roles | C3: =CALC!L4 -> 0 | D3: =CALC!M4 -> 0 | E3: =CALC!N4 -> 0 | F3: =CALC!O4 -> 0
A4: =_xlfn.CONCAT($A$1, ".", CALC!A5) -> LSD.RID.0.AL.LFPR.1 | B4: =_xlfn.CONCAT(CALC!B5, ":", CALC!C5) -> Agriculture:Support | C4: =CALC!L5 -> 0 | D4: =CALC!M5 -> 0 | E4: =CALC!N5 -> 0 | F4: =CALC!O5 -> 0
A5: =_xlfn.CONCAT($A$1, ".", CALC!A6) -> LSD.RID.0.AL.LFPR.2 | B5: =_xlfn.CONCAT(CALC!B6, ":", CALC!C6) -> Agriculture:Worker | C5: =CALC!L6 -> 0 | D5: =CALC!M6 -> 0 | E5: =CALC!N6 -> 0 | F5: =CALC!O6 -> 0
A6: =_xlfn.CONCAT($A$1, ".", CALC!A7) -> LSD.RID.0.AL.LFPR.3 | B6: =_xlfn.CONCAT(CALC!B7, ":", CALC!C7) -> Construction:Support | C6: =CALC!L7 -> 0 | D6: =CALC!M7 -> 0 | E6: =CALC!N7 -> 0 | F6: =CALC!O7 -> 0
A7: =_xlfn.CONCAT($A$1, ".", CALC!A8) -> LSD.RID.0.AL.LFPR.4 | B7: =_xlfn.CONCAT(CALC!B8, ":", CALC!C8) -> Construction:Worker | C7: =CALC!L8 -> 0 | D7: =CALC!M8 -> 0 | E7: =CALC!N8 -> 0 | F7: =CALC!O8 -> 0
A8: =_xlfn.CONCAT($A$1, ".", CALC!A9) -> LSD.RID.0.AL.LFPR.5 | B8: =_xlfn.CONCAT(CALC!B9, ":", CALC!C9) -> Hospitality:Support | C8: =CALC!L9 -> 0 | D8: =CALC!M9 -> 0 | E8: =CALC!N9 -> 0 | F8: =CALC!O9 -> 0
